Workbook
Name A2ca17: 'Eq7 avec Sent_t'!$A$2

Sheet ALL VARS
A1: Date | B1: Close price | C1: Daily Return | D1: Daily_aggregate_sentiment | F1: Daily Return_t_+1 | G1: Daily Return_t | H1: Daily Return_t_minus_1 | I1: Daily aggregate sentiment_t+1 | J1: VIX_10_t | K1: VIX_bar_10 | L1: VIX_10_t minus VIX_bar_10 | M1: Sent_t | N1: ck | O1: ck | P1: Sent_t_+_1 | Q1: Sent_t * (VIX_10_t minus VIX_bar_10) | R1: Sent_t_+_1 * (VIX_10_t minus VIX_bar_10) | S1: Sent_t_k, k=0 | T1: Sent_t_+_1_k, k=0 | U1: Sent_t_k, k=0 * (VIX_10_t minus VIX_bar_10) | V1: Sent_t_+_1_k, k=0 * (VIX_10_t minus VIX_bar_10) | W1: Sent_t_k, k=1 | X1: Sent_t_+_1_k, k=1 | Y1: Sent_t_k, k=1 * (VIX_10_t minus VIX_bar_10) | Z1: Sent_t_+_1_k, k=1 * (VIX_10_t minus VIX_bar_10) | AA1: Sent_t_k, k=2 | AB1: Sent_t_+_1_k, k=2 | AC1: Sent_t_k, k=2 * (VIX_10_t minus VIX_bar_10) | AD1: Sent_t_+_1_k, k=2 * (VIX_10_t minus VIX_bar_10) | AE1: Sent_t_k, k=3 | AF1: Sent_t_+_1_k, k=3 | AG1: Sent_t_k, k=3 * (VIX_10_t minus VIX_bar_10) | AH1: Sent_t_+_1_k, k=3 * (VIX_10_t minus VIX_bar_10) | AI1: Sent_t_k, k=4 | AJ1: Sent_t_+_1_k, k=4 | AK1: Sent_t_k, k=4 * (VIX_10_t minus VIX_bar_10) | AL1: Sent_t_+_1_k, k=4 * (VIX_10_t minus VIX_bar_10) | AM1: Sent_t_k, k=5 | AN1: Sent_t_+_1_k, k=5 | AO1: Sent_t_k, k=5 * (VIX_10_t minus VIX_bar_10) | AP1: Sent_t_+_1_k, k=5 * (VIX_10_t minus VIX_bar_10) | AQ1: Sent_t_k, k=6 | AR1: Sent_t_+_1_k, k=6 | AS1: Sent_t_k, k=6 * (VIX_10_t minus VIX_bar_10) | AT1: Sent_t_+_1_k, k=6 * (VIX_10_t minus VIX_bar_10) | AU1: Sent_t_k, k=7 | AV1: Sent_t_+_1_k, k=7 | AW1: Sent_t_k, k=7 * (VIX_10_t minus VIX_bar_10) | AX1: Sent_t_+_1_k, k=7 * (VIX_10_t minus VIX_bar_10) | AY1: Sent_t_k, k=8 | AZ1: Sent_t_+_1_k, k=8 | BA1: Sent_t_k, k=8 * (VIX_10_t minus VIX_bar_10) | BB1: Sent_t_+_1_k, k=8 * (VIX_10_t minus VIX_bar_10) | BC1: Sent_t_k, k=9 | BD1: Sent_t_+_1_k, k=9 | BE1: Sent_t_k, k=9 * (VIX_10_t minus VIX_bar_10) | BF1: Sent_t_+_1_k, k=9 * (VIX_10_t minus VIX_bar_10) | BH1: Sent_t | BI1: Sent_t * (VIX_10_t minus VIX_bar_10) | BJ1: Sent_t_k, k=0 | BK1: Sent_t_k, k=0 * (VIX_10_t minus VIX_bar_10) | BL1: Sent_t_k, k=1 | BM1: Sent_t_k, k=1 * (VIX_10_t minus VIX_bar_10) | BN1: Sent_t_k, k=2 | BO1: Sent_t_k, k=2 * (VIX_10_t minus VIX_bar_10) | BP1: Sent_t_k, k=3 | BQ1: Sent_t_k, k=3 * (VIX_10_t minus VIX_bar_10) | BR1: Sent_t_k, k=4 | BS1: Sent_t_k, k=4 * (VIX_10_t minus VIX_bar_10) | BT1: Sent_t_k, k=5 | BU1: Sent_t_k, k=5 * (VIX_10_t minus VIX_bar_10) | BV1: Sent_t_k, k=6 | BW1: Sent_t_k, k=6 * (VIX_10_t minus VIX_bar_10) | BX1: Sent_t_k, k=7 | BY1: Sent_t_k, k=7 * (VIX_10_t minus VIX_bar_10) | BZ1: Sent_t_k, k=8 | CA1: Sent_t_k, k=8 * (VIX_10_t minus VIX_bar_10) | CB1: Sent_t_k, k=9 | CC1: Sent_t_k, k=9 * (VIX_10_t minus VIX_bar_10) | CD1: VIX_10_t | CE1: ck
A2: 43913 | B2: 205.04 | C2: 0.054244434 | D2: 0.096464223 | F2: 0.12475615 | G2: 0.054244434 | H2: -0.057383803 | I2: 0.096464223 | J2: 66.205001 | K2: 45.214509 | L2: 20.990492 | M2: 0.096464223 | N2: TRUE | O2: TRUE | P2: -0.10538955 | Q2: 2.0248315 | R2: -2.2121785 | S2: 0.016987293 | T2: -0.0049289412 | U2: 0.35657162 | V2: -0.1034609 | W2: 0.010154785 | X2: -0.0051828275 | Y2: 0.21315393 | Z2: -0.1087901 | AA2: 0.0017143712 | AB2: -0.0083667689 | AC2: 0.035985495 | AD2: -0.17562259 | AE2: 0.001714303 | AF2: -0.0093807704 | AG2: 0.035984063 | AH2: -0.19690698 | AI2: 0.010154697 | AJ2: -0.009853285 | AK2: 0.21315208 | AL2: -0.2068253 | AM2: 0.0017143928 | AN2: -0.0042560109 | AO2: 0.035985948 | AP2: -0.089335762 | AQ2: 0.0017143413 | AR2: -0.012885692 | AS2: 0.035984867 | AT2: -0.27047702 | AU2: 0.019058173 | AV2: -0.026128404 | AW2: 0.40004043 | AX2: -0.54844805 | AY2: 0.023097021 | AZ2: -0.016409398 | BA2: 0.48481783 | BB2: -0.34444132 | BC2: 0.010154845 | BD2: -0.0079974543 | BE2: 0.2131552 | BF2: -0.1678705 | BH2: 0.096464223 | BI2: 2.0248315 | BJ2: 0.016987293 | BK2: 0.35657162 | BL2: 0.010154785 | BM2: 0.21315393 | BN2: 0.0017143712 | BO2: 0.035985495 | BP2: 0.001714303 | BQ2: 0.035984063 | BR2: 0.010154697 | BS2: 0.21315208 | BT2: 0.0017143928 | BU2: 0.035985948 | BV2: 0.0017143413 | BW2: 0.035984867 | BX2: 0.019058173 | BY2: 0.40004043 | BZ2: 0.023097021 | CA2: 0.48481783 | CB2: 0.010154845 | CC2: 0.2131552 | CD2: 66.205001 | CE2: TRUE
A3: 43910 | B3: 194.49 | C3: -0.057383803 | D3: -0.26341802 | F3: 0.054244434 | G3: -0.057383803 | H3: 0.045608879 | I3: -0.26341802 | J3: 63.795 | K3: 45.214509 | L3: 18.580491 | M3: -0.26341802 | N3: TRUE | O3: TRUE | P3: 0.096464223 | Q3: -4.8944363 | R3: 1.7923527 | S3: -0.0055165897 | T3: 0.016987293 | U3: -0.10250095 | V3: 0.31563224 | W3: -0.0055161055 | X3: 0.010154785 | Y3: -0.10249195 | Z3: 0.18868089 | AA3: -0.0055161516 | AB3: 0.0017143712 | AC3: -0.10249281 | AD3: 0.03185386 | AE3: -0.0055164069 | AF3: 0.001714303 | AG3: -0.10249755 | AH3: 0.031852592 | AI3: -0.03112574 | AJ3: 0.010154697 | AK3: -0.57833154 | AL3: 0.18867926 | AM3: -0.0055163964 | AN3: 0.0017143928 | AO3: -0.10249736 | AP3: 0.031854261 | AQ3: -0.07624635 | AR3: 0.0017143413 | AS3: -1.4166947 | AT3: 0.031853305 | AU3: -0.030603371 | AV3: 0.019058173 | AW3: -0.56862567 | AX3: 0.35411023 | AY3: -0.067954531 | AZ3: 0.023097021 | BA3: -1.2626286 | BB3: 0.42915401 | BC3: -0.029906382 | BD3: 0.010154845 | BE3: -0.55567527 | BF3: 0.18868202 | BH3: -0.26341802 | BI3: -4.8944363 | BJ3: -0.0055165897 | BK3: -0.10250095 | BL3: -0.0055161055 | BM3: -0.10249195 | BN3: -0.0055161516 | BO3: -0.10249281 | BP3: -0.0055164069 | BQ3: -0.10249755 | BR3: -0.03112574 | BS3: -0.57833154 | BT3: -0.0055163964 | BU3: -0.10249736 | BV3: -0.07624635 | BW3: -1.4166947 | BX3: -0.030603371 | BY3: -0.56862567 | BZ3: -0.067954531 | CA3: -1.2626286 | CB3: -0.029906382 | CC3: -0.55567527 | CD3: 63.795 | CE3: TRUE
A4: 43909 | B4: 206.33 | C4: 0.045608879 | D4: -0.010060928 | F4: -0.057383803 | G4: 0.045608879 | H4: -0.090980284 | I4: -0.010060928 | J4: 60.557 | K4: 45.214509 | L4: 15.342491 | M4: -0.010060928 | N4: TRUE | O4: TRUE | P4: -0.26341802 | Q4: -0.1543597 | R4: -4.0414888 | S4: -0.00017128678 | T4: -0.0055165897 | U4: -0.002627966 | V4: -0.08463823 | W4: -0.00017128525 | X4: -0.0055161055 | Y4: -0.0026279425 | Z4: -0.084630801 | AA4: -0.0017174014 | AB4: -0.0055161516 | AC4: -0.026349216 | AD4: -0.084631508 | AE4: -0.0005472193 | AF4: -0.0055164069 | AG4: -0.0083957074 | AH4: -0.084635425 | AI4: -0.00055334375 | AJ4: -0.03112574 | AK4: -0.0084896717 | AL4: -0.47754639 | AM4: -0.00085723562 | AN4: -0.0055163964 | AO4: -0.01315213 | AP4: -0.084635264 | AQ4: -0.00097158339 | AR4: -0.07624635 | AS4: -0.01490651 | AT4: -1.169809 | AU4: -0.0030150896 | AV4: -0.030603371 | AW4: -0.046258986 | AX4: -0.46953195 | AY4: -0.0010849323 | AZ4: -0.067954531 | BA4: -0.016645565 | BB4: -1.0425918 | BC4: -0.0009715503 | BD4: -0.029906382 | BE4: -0.014906002 | BF4: -0.4588384 | BH4: -0.010060928 | BI4: -0.1543597 | BJ4: -0.00017128678 | BK4: -0.002627966 | BL4: -0.00017128525 | BM4: -0.0026279425 | BN4: -0.0017174014 | BO4: -0.026349216 | BP4: -0.0005472193 | BQ4: -0.0083957074 | BR4: -0.00055334375 | BS4: -0.0084896717 | BT4: -0.00085723562 | BU4: -0.01315213 | BV4: -0.00097158339 | BW4: -0.01490651 | BX4: -0.0030150896 | BY4: -0.046258986 | BZ4: -0.0010849323 | CA4: -0.016645565 | CB4: -0.0009715503 | CC4: -0.014906002 | CD4: 60.557 | CE4: TRUE
A5: 43908 | B5: 197.33 | C5: -0.090980284 | D5: -0.20595118 | F5: 0.045608879 | G5: -0.090980284 | H5: 0.091896786 | I5: -0.20595118 | J5: 56.111001 | K5: 45.214509 | L5: 10.896492 | M5: -0.20595118 | N5: TRUE | O5: TRUE | P5: -0.010060928 | Q5: -2.2441454 | R5: -0.10962881 | S5: -0.034952246 | T5: -0.00017128678 | U5: -0.38085685 | V5: -0.001866425 | W5: -0.0040604122 | X5: -0.00017128525 | Y5: -0.044244248 | Z5: -0.0018664083 | AA5: -0.0040605107 | AB5: -0.0017174014 | AC5: -0.044245322 | AD5: -0.01871365 | AE5: -0.0040604921 | AF5: -0.0005472193 | AG5: -0.044245119 | AH5: -0.0059627706 | AI5: -0.039365742 | AJ5: -0.00055334375 | AK5: -0.42894848 | AL5: -0.0060295055 | AM5: -0.0040604791 | AN5: -0.00085723562 | AO5: -0.044244977 | AP5: -0.0093408609 | AQ5: -0.0040606006 | AR5: -0.00097158339 | AS5: -0.044246301 | AT5: -0.01058685 | AU5: -0.072317029 | AV5: -0.0030150896 | AW5: -0.7880019 | AX5: -0.032853898 | AY5: -0.034953075 | AZ5: -0.0010849323 | BA5: -0.38086589 | BB5: -0.011821956 | BC5: -0.0040605986 | BD5: -0.0009715503 | BE5: -0.044246279 | BF5: -0.01058649 | BH5: -0.20595118 | BI5: -2.2441454 | BJ5: -0.034952246 | BK5: -0.38085685 | BL5: -0.0040604122 | BM5: -0.044244248 | BN5: -0.0040605107 | BO5: -0.044245322 | BP5: -0.0040604921 | BQ5: -0.044245119 | BR5: -0.039365742 | BS5: -0.42894848 | BT5: -0.0040604791 | BU5: -0.044244977 | BV5: -0.0040606006 | BW5: -0.044246301 | BX5: -0.072317029 | BY5: -0.7880019 | BZ5: -0.034953075 | CA5: -0.38086589 | CB5: -0.0040605986 | CC5: -0.044246279 | CD5: 56.111001 | CE5: TRUE
A6: 43907 | B6: 217.08 | C6: 0.091896786 | D6: -0.11883066 | F6: -0.090980284 | G6: 0.091896786 | H6: 0.026592998 | I6: -0.11883066 | J6: 52.202 | K6: 45.214509 | L6: 6.9874913 | M6: -0.11883066 | N6: TRUE | O6: TRUE | P6: -0.20595118 | Q6: -0.83032818 | R6: -1.4390821 | S6: -0.0015805664 | T6: -0.034952246 | U6: -0.011044194 | V6: -0.24422851 | W6: -0.0091976094 | X6: -0.0040604122 | Y6: -0.064268216 | Z6: -0.028372095 | AA6: -0.017032331 | AB6: -0.0040605107 | AC6: -0.11901326 | AD6: -0.028372783 | AE6: -0.0098072255 | AF6: -0.0040604921 | AG6: -0.068527903 | AH6: -0.028372653 | AI6: -0.0099596077 | AJ6: -0.039365742 | AK6: -0.069592672 | AL6: -0.27506778 | AM6: -0.016797308 | AN6: -0.0040604791 | AO6: -0.11737105 | AP6: -0.028372562 | AQ6: -0.0038836146 | AR6: -0.0040606006 | AS6: -0.027136723 | AT6: -0.028373411 | AU6: -0.025701973 | AV6: -0.072317029 | AW6: -0.17959231 | AX6: -0.50531461 | AY6: -0.015672602 | AZ6: -0.034953075 | BA6: -0.10951217 | BB6: -0.24423431 | BC6: -0.0091978201 | BD6: -0.0040605986 | BE6: -0.064269688 | BF6: -0.028373398 | BH6: -0.11883066 | BI6: -0.83032818 | BJ6: -0.0015805664 | BK6: -0.011044194 | BL6: -0.0091976094 | BM6: -0.064268216 | BN6: -0.017032331 | BO6: -0.11901326 | BP6: -0.0098072255 | BQ6: -0.068527903 | BR6: -0.0099596077 | BS6: -0.069592672 | BT6: -0.016797308 | BU6: -0.11737105 | BV6: -0.0038836146 | BW6: -0.027136723 | BX6: -0.025701973 | BY6: -0.17959231 | BZ6: -0.015672602 | CA6: -0.10951217 | CB6: -0.0091978201 | CC6: -0.064269688 | CD6: 52.202 | CE6: TRUE
A7: 43906 | B7: 198.81 | C7: 0.026592998 | D7: 0.03190722 | F7: 0.091896786 | G7: 0.026592998 | H7: -0.035941856 | I7: 0.03190722 | J7: 47.275 | K7: 45.214509 | L7: 2.0604909 | M7: 0.03190722 | N7: TRUE | O7: TRUE | P7: -0.11883066 | Q7: 0.065744536 | R7: -0.24484949 | S7: 0.00058939209 | T7: -0.0015805664 | U7: 0.001214437 | V7: -0.0032567426 | W7: 0.00058937332 | X7: -0.0091976094 | Y7: 0.0012143983 | Z7: -0.01895159 | AA7: 0.0076543061 | AB7: -0.017032331 | AC7: 0.015771628 | AD7: -0.035094962 | AE7: 0.00058939635 | AF7: -0.0098072255 | AG7: 0.0012144458 | AH7: -0.020207699 | AI7: 0.00058933216 | AJ7: -0.0099596077 | AK7: 0.0012143135 | AL7: -0.020521681 | AM7: 0.00058935239 | AN7: -0.016797308 | AO7: 0.0012143552 | AP7: -0.034610701 | AQ7: 0.0043877431 | AR7: -0.0038836146 | AS7: 0.0090409047 | AT7: -0.0080021524 | AU7: 0.0082946416 | AV7: -0.025701973 | AW7: 0.017091034 | AX7: -0.05295868 | AY7: 0.0080343301 | AZ7: -0.015672602 | BA7: 0.016554664 | BB7: -0.032293254 | BC7: 0.00058935291 | BD7: -0.0091978201 | BE7: 0.0012143563 | BF7: -0.018952024 | BH7: 0.03190722 | BI7: 0.065744536 | BJ7: 0.00058939209 | BK7: 0.001214437 | BL7: 0.00058937332 | BM7: 0.0012143983 | BN7: 0.0076543061 | BO7: 0.015771628 | BP7: 0.00058939635 | BQ7: 0.0012144458 | BR7: 0.00058933216 | BS7: 0.0012143135 | BT7: 0.00058935239 | BU7: 0.0012143552 | BV7: 0.0043877431 | BW7: 0.0090409047 | BX7: 0.0082946416 | BY7: 0.017091034 | BZ7: 0.0080343301 | CA7: 0.016554664 | CB7: 0.00058935291 | CC7: 0.0012143563 | CD7: 47.275 | CE7: TRUE
A8: 43903 | B8: 193.66 | C8: -0.035941856 | D8: -0.35427595 | F8: 0.026592998 | G8: -0.035941856 | H8: -0.10349444 | I8: -0.35427595 | J8: 45.503 | K8: 45.214509 | L8: 0.28849079 | M8: -0.35427595 | N8: TRUE | O8: TRUE | P8: 0.03190722 | Q8: -0.10220535 | R8: 0.009204939 | S8: -0.0055254527 | T8: 0.00058939209 | U8: -0.0015940422 | V8: 0.00017003419 | W8: -0.036524204 | X8: 0.00058937332 | Y8: -0.010536896 | Z8: 0.00017002877 | AA8: -0.035048006 | AB8: 0.0076543061 | AC8: -0.010111027 | AD8: 0.0022081968 | AE8: -0.049581885 | AF8: 0.00058939635 | AG8: -0.014303917 | AH8: 0.00017003542 | AI8: -0.0055254381 | AJ8: 0.00058933216 | AK8: -0.001594038 | AL8: 0.0001700169 | AM8: -0.0055255973 | AN8: 0.00058935239 | AO8: -0.0015940839 | AP8: 0.00017002274 | AQ8: -0.03027812 | AR8: 0.0043877431 | AS8: -0.0087349585 | AT8: 0.0012658235 | AU8: -0.10358094 | AV8: 0.0082946416 | AW8: -0.029882146 | AX8: 0.0023929277 | AY8: -0.04763828 | AZ8: 0.0080343301 | BA8: -0.013743205 | BB8: 0.0023178302 | BC8: -0.035048028 | BD8: 0.00058935291 | BE8: -0.010111033 | BF8: 0.00017002288 | BH8: -0.35427595 | BI8: -0.10220535 | BJ8: -0.0055254527 | BK8: -0.0015940422 | BL8: -0.036524204 | BM8: -0.010536896 | BN8: -0.035048006 | BO8: -0.010111027 | BP8: -0.049581885 | BQ8: -0.014303917 | BR8: -0.0055254381 | BS8: -0.001594038 | BT8: -0.0055255973 | BU8: -0.0015940839 | BV8: -0.03027812 | BW8: -0.0087349585 | BX8: -0.10358094 | BY8: -0.029882146 | BZ8: -0.04763828 | CA8: -0.013743205 | CB8: -0.035048028 | CC8: -0.010111033 | CD8: 45.503 | CE8: TRUE
A9: 43902 | B9: 200.88 | C9: -0.10349444 | D9: -0.067783173 | F9: -0.035941856 | G9: -0.10349444 | H9: -0.065869012 | I9: -0.067783173 | J9: 41.872 | K9: 45.214509 | L9: -3.3425093 | M9: -0.067783173 | N9: TRUE | O9: TRUE | P9: -0.35427595 | Q9: 0.22656589 | R9: 1.1841707 | S9: -0.0070630843 | T9: -0.0055254527 | U9: 0.023608425 | V9: 0.018468877 | W9: -0.0010380612 | X9: -0.036524204 | Y9: 0.0034697293 | Z9: 0.12208249 | AA9: -0.012657981 | AB9: -0.035048006 | AC9: 0.04230942 | AD9: 0.11714829 | AE9: -0.0064605697 | AF9: -0.049581885 | AG9: 0.021594514 | AH9: 0.16572791 | AI9: -0.0070631412 | AJ9: -0.0055254381 | AK9: 0.023608615 | AL9: 0.018468828 | AM9: -0.0069688562 | AN9: -0.0055255973 | AO9: 0.023293467 | AP9: 0.018469361 | AQ9: -0.0010381496 | AR9: -0.03027812 | AS9: 0.0034700247 | AT9: 0.1012049 | AU9: -0.018066302 | AV9: -0.10358094 | AW9: 0.060386782 | AX9: 0.34622025 | AY9: -0.0063888337 | AZ9: -0.04763828 | BA9: 0.021354736 | BB9: 0.1592314 | BC9: -0.0010381946 | BD9: -0.035048028 | BE9: 0.0034701751 | BF9: 0.11714836 | BH9: -0.067783173 | BI9: 0.22656589 | BJ9: -0.0070630843 | BK9: 0.023608425 | BL9: -0.0010380612 | BM9: 0.0034697293 | BN9: -0.012657981 | BO9: 0.04230942 | BP9: -0.0064605697 | BQ9: 0.021594514 | BR9: -0.0070631412 | BS9: 0.023608615 | BT9: -0.0069688562 | BU9: 0.023293467 | BV9: -0.0010381496 | BW9: 0.0034700247 | BX9: -0.018066302 | BY9: 0.060386782 | BZ9: -0.0063888337 | CA9: 0.021354736 | CB9: -0.0010381946 | CC9: 0.0034701751 | CD9: 41.872 | CE9: TRUE
A10: 43901 | B10: 224.07 | C10: -0.065869012 | D10: -0.056557501 | F10: -0.10349444 | G10: -0.065869012 | H10: 0.013692262 | I10: -0.056557501 | J10: 39.237999 | K10: 45.214509 | L10: -5.9765096 | M10: -0.056557501 | N10: TRUE | O10: TRUE | P10: -0.067783173 | Q10: 0.33801645 | R10: 0.40510679 | S10: -0.00712793 | T10: -0.0070630843 | U10: 0.042600142 | V10: 0.042212591 | W10: -0.00088192819 | X10: -0.0010380612 | Y10: 0.0052708523 | Z10: 0.0062039828 | AA10: -0.008637216 | AB10: -0.012657981 | AC10: 0.051620405 | AD10: 0.075650547 | AE10: -0.010756835 | AF10: -0.0064605697 | AG10: 0.064288328 | AH10: 0.038611657 | AI10: -0.0058305821 | AJ10: -0.0070631412 | AK10: 0.03484653 | AL10: 0.042212931 | AM10: -0.00088197054 | AN10: -0.0069688562 | AO10: 0.0052711054 | AP10: 0.041649436 | AQ10: -0.0055948988 | AR10: -0.0010381496 | AS10: 0.033437966 | AT10: 0.0062045111 | AU10: -0.0092237513 | AV10: -0.018066302 | AW10: 0.055125839 | AX10: 0.10797343 | AY10: -0.0051236745 | AZ10: -0.0063888337 | BA10: 0.03062169 | BB10: 0.038182926 | BC10: -0.0024987144 | BD10: -0.0010381946 | BE10: 0.014933591 | BF10: 0.0062047799 | BH10: -0.056557501 | BI10: 0.33801645 | BJ10: -0.00712793 | BK10: 0.042600142 | BL10: -0.00088192819 | BM10: 0.0052708523 | BN10: -0.008637216 | BO10: 0.051620405 | BP10: -0.010756835 | BQ10: 0.064288328 | BR10: -0.0058305821 | BS10: 0.03484653 | BT10: -0.00088197054 | BU10: 0.0052711054 | BV10: -0.0055948988 | BW10: 0.033437966 | BX10: -0.0092237513 | BY10: 0.055125839 | BZ10: -0.0051236745 | CA10: 0.03062169 | CB10: -0.0024987144 | CC10: 0.014933591 | CD10: 39.237999 | CE10: TRUE
A11: 43900 | B11: 239.87 | C11: 0.013692262 | D11: 0.043987866 | F11: -0.065869012 | G11: 0.013692262 | H11: -0.072693785 | I11: 0.043987866 | J11: 37.293 | K11: 45.214509 | L11: -7.9215095 | M11: 0.043987866 | N11: TRUE | O11: TRUE | P11: -0.056557501 | Q11: -0.3484503 | R11: 0.44802078 | S11: 0.0061216104 | T11: -0.00712793 | U11: -0.048492395 | V11: 0.056463965 | W11: 0.00088501541 | X11: -0.00088192819 | Y11: -0.007010658 | Z11: 0.0069862026 | AA11: 0.00088509334 | AB11: -0.008637216 | AC11: -0.0070112754 | AD11: 0.068419789 | AE11: 0.0025828414 | AF11: -0.010756835 | AG11: -0.020460003 | AH11: 0.085210371 | AI11: 0.00088501926 | AJ11: -0.0058305821 | AK11: -0.0070106885 | AL11: 0.046187011 | AM11: 0.00088504982 | AN11: -0.00088197054 | AO11: -0.0070109306 | AP11: 0.0069865381 | AQ11: 0.0082161793 | AR11: -0.0055948988 | AS11: -0.065084542 | AT11: 0.044320044 | AU11: 0.0078545739 | AV11: -0.0092237513 | AW11: -0.062220082 | AX11: 0.073066034 | AY11: 0.014787363 | AZ11: -0.0051236745 | BA11: -0.11713824 | BB11: 0.040587236 | BC11: 0.00088511996 | BD11: -0.0024987144 | BE11: -0.0070114862 | BF11: 0.01979359 | BH11: 0.043987866 | BI11: -0.3484503 | BJ11: 0.0061216104 | BK11: -0.048492395 | BL11: 0.00088501541 | BM11: -0.007010658 | BN11: 0.00088509334 | BO11: -0.0070112754 | BP11: 0.0025828414 | BQ11: -0.020460003 | BR11: 0.00088501926 | BS11: -0.0070106885 | BT11: 0.00088504982 | BU11: -0.0070109306 | BV11: 0.0082161793 | BW11: -0.065084542 | BX11: 0.0078545739 | BY11: -0.062220082 | BZ11: 0.014787363 | CA11: -0.11713824 | CB11: 0.00088511996 | CC11: -0.0070114862 | CD11: 37.293 | CE11: TRUE

Sheet Close price
A1: ='ALL VARS'!A1 -> Date | B1: ='ALL VARS'!B1 -> Close price
A2: ='ALL VARS'!A2 -> 43913 | B2: ='ALL VARS'!B2 -> 205.04
A3: ='ALL VARS'!A3 -> 43910 | B3: ='ALL VARS'!B3 -> 194.49
A4: ='ALL VARS'!A4 -> 43909 | B4: ='ALL VARS'!B4 -> 206.33
A5: ='ALL VARS'!A5 -> 43908 | B5: ='ALL VARS'!B5 -> 197.33
A6: ='ALL VARS'!A6 -> 43907 | B6: ='ALL VARS'!B6 -> 217.08
A7: ='ALL VARS'!A7 -> 43906 | B7: ='ALL VARS'!B7 -> 198.81
A8: ='ALL VARS'!A8 -> 43903 | B8: ='ALL VARS'!B8 -> 193.66
A9: ='ALL VARS'!A9 -> 43902 | B9: ='ALL VARS'!B9 -> 200.88
A10: ='ALL VARS'!A10 -> 43901 | B10: ='ALL VARS'!B10 -> 224.07
A11: ='ALL VARS'!A11 -> 43900 | B11: ='ALL VARS'!B11 -> 239.87
D20: Max | E20: =MAX(B2:B11) -> 239.87
D21: Q3 | E21: =QUARTILE(B2:B11, 3) -> 214.3925
D22: Median | E22: =MEDIAN(B2:B11) -> 202.96
D23: Q1 | E23: =QUARTILE(B2:B11, 1) -> 197.7
D24: Min | E24: =MIN(B2:B11) -> 193.66

Sheet Eq4 avec Sent_t__+__1
A1: ='ALL VARS'!A1 -> Date | B1: ='ALL VARS'!F1 -> Daily Return_t_+1 | C1: ='ALL VARS'!G1 -> Daily Return_t | D1: ='ALL VARS'!H1 -> Daily Return_t_minus_1 | E1: ='ALL VARS'!P1 -> Sent_t_+_1 | F1: ='ALL VARS'!R1 -> Sent_t_+_1 * (VIX_10_t minus VIX_bar_10) | G1: ='ALL VARS'!J1 -> VIX_10_t
A2: ='ALL VARS'!A2 -> 43913 | B2: ='ALL VARS'!F2 -> 0.12475615 | C2: ='ALL VARS'!G2 -> 0.054244434 | D2: ='ALL VARS'!H2 -> -0.057383803 | E2: ='ALL VARS'!P2 -> -0.10538955 | F2: ='ALL VARS'!R2 -> -2.2121785 | G2: ='ALL VARS'!J2 -> 66.205001 | I2: RAPPORT DÉTAILLÉ
A3: ='ALL VARS'!A3 -> 43910 | B3: ='ALL VARS'!F3 -> 0.054244434 | C3: ='ALL VARS'!G3 -> -0.057383803 | D3: ='ALL VARS'!H3 -> 0.045608879 | E3: ='ALL VARS'!P3 -> 0.096464223 | F3: ='ALL VARS'!R3 -> 1.7923527 | G3: ='ALL VARS'!J3 -> 63.795
A4: ='ALL VARS'!A4 -> 43909 | B4: ='ALL VARS'!F4 -> -0.057383803 | C4: ='ALL VARS'!G4 -> 0.045608879 | D4: ='ALL VARS'!H4 -> -0.090980284 | E4: ='ALL VARS'!P4 -> -0.26341802 | F4: ='ALL VARS'!R4 -> -4.0414888 | G4: ='ALL VARS'!J4 -> 60.557 | I4: Statistiques de la régression
A5: ='ALL VARS'!A5 -> 43908 | B5: ='ALL VARS'!F5 -> 0.045608879 | C5: ='ALL VARS'!G5 -> -0.090980284 | D5: ='ALL VARS'!H5 -> 0.091896786 | E5: ='ALL VARS'!P5 -> -0.010060928 | F5: ='ALL VARS'!R5 -> -0.10962881 | G5: ='ALL VARS'!J5 -> 56.111001 | I5: Coefficient de détermination multiple | J5: 0.47852726
A6: ='ALL VARS'!A6 -> 43907 | B6: ='ALL VARS'!F6 -> -0.090980284 | C6: ='ALL VARS'!G6 -> 0.091896786 | D6: ='ALL VARS'!H6 -> 0.026592998 | E6: ='ALL VARS'!P6 -> -0.20595118 | F6: ='ALL VARS'!R6 -> -1.4390821 | G6: ='ALL VARS'!J6 -> 52.202 | I6: Coefficient de détermination R^2 | J6: 0.22898834
A7: ='ALL VARS'!A7 -> 43906 | B7: ='ALL VARS'!F7 -> 0.091896786 | C7: ='ALL VARS'!G7 -> 0.026592998 | D7: ='ALL VARS'!H7 -> -0.035941856 | E7: ='ALL VARS'!P7 -> -0.11883066 | F7: ='ALL VARS'!R7 -> -0.24484949 | G7: ='ALL VARS'!J7 -> 47.275 | I7: Coefficient de détermination R^2 | J7: -0.58782098
A8: ='ALL VARS'!A8 -> 43903 | B8: ='ALL VARS'!F8 -> 0.026592998 | C8: ='ALL VARS'!G8 -> -0.035941856 | D8: ='ALL VARS'!H8 -> -0.10349444 | E8: ='ALL VARS'!P8 -> 0.03190722 | F8: ='ALL VARS'!R8 -> 0.009204939 | G8: ='ALL VARS'!J8 -> 45.503 | I8: Erreur-type | J8: 0.094286273
A9: ='ALL VARS'!A9 -> 43902 | B9: ='ALL VARS'!F9 -> -0.035941856 | C9: ='ALL VARS'!G9 -> -0.10349444 | D9: ='ALL VARS'!H9 -> -0.065869012 | E9: ='ALL VARS'!P9 -> -0.35427595 | F9: ='ALL VARS'!R9 -> 1.1841707 | G9: ='ALL VARS'!J9 -> 41.872 | I9: Observations | J9: 10
A10: ='ALL VARS'!A10 -> 43901 | B10: ='ALL VARS'!F10 -> -0.10349444 | C10: ='ALL VARS'!G10 -> -0.065869012 | D10: ='ALL VARS'!H10 -> 0.013692262 | E10: ='ALL VARS'!P10 -> -0.067783173 | F10: ='ALL VARS'!R10 -> 0.40510679 | G10: ='ALL VARS'!J10 -> 39.237999
A11: ='ALL VARS'!A11 -> 43900 | B11: ='ALL VARS'!F11 -> -0.065869012 | C11: ='ALL VARS'!G11 -> 0.013692262 | D11: ='ALL VARS'!H11 -> -0.072693785 | E11: ='ALL VARS'!P11 -> -0.056557501 | F11: ='ALL VARS'!R11 -> 0.44802078 | G11: ='ALL VARS'!J11 -> 37.293 | I11: ANALYSE DE VARIANCE
J12: Degré de liberté | K12: Somme des carrés | L12: Moyenne des carrés | M12: F | N12: Valeur critique de F
I13: Régression | J13: 5 | K13: 0.013201381 | L13: 0.0026402762 | M13: 0.29699725 | N13: 0.89232807
I14: Résidus | J14: 5 | K14: 0.044449506 | L14: 0.0088899013
I15: Total | J15: 10 | K15: 0.057650887
J17: Coefficients | K17: Erreur-type | L17: Statistique t | M17: Probabilité | N17: Limite inférieure pour seuil de confiance = 95% | O17: Limite supérieure pour seuil de confiance = 95% | P17: Limite inférieure pour seuil de confiance = 95,0% | Q17: Limite supérieure pour seuil de confiance = 95,0%
I18: Constante | J18: 0 | K18: #N/A | L18: #N/A | M18: #N/A | N18: #N/A | O18: #N/A | P18: #N/A | Q18: #N/A
I19: Daily Return_t | J19: -0.0042370303 | K19: 0.66536656 | L19: -0.006367964 | M19: 0.9951654 | N19: -1.7146162 | O19: 1.7061422 | P19: -1.7146162 | Q19: 1.7061422
I20: Daily Return_t_minus_1 | J20: -0.13155326 | K20: 0.52651609 | L20: -0.2498561 | M20: 0.81263939 | N20: -1.485006 | O20: 1.2218994 | P20: -1.485006 | Q20: 1.2218994
I21: Sent_t_+_1 | J21: 0.29567464 | K21: 0.25490823 | L21: 1.1599258 | M21: 0.29845184 | N21: -0.35958782 | O21: 0.9509371 | P21: -0.35958782 | Q21: 0.9509371
I22: Sent_t_+_1 * (VIX_10_t minus VIX_bar_10) | J22: -0.004338397 | K22: 0.028526349 | L22: -0.15208385 | M22: 0.88506708 | N22: -0.077667712 | O22: 0.068990918 | P22: -0.077667712 | Q22: 0.068990918
I23: VIX_10_t | J23: 0.0005997821 | K23: 0.0007609819 | L23: 0.78816869 | M23: 0.46630405 | N23: -0.0013563841 | O23: 0.0025559483 | P23: -0.0013563841 | Q23: 0.0025559483

Sheet Eq4 avec Sent__t_+_1_k, k=0
A1: ='ALL VARS'!A1 -> Date | B1: ='ALL VARS'!F1 -> Daily Return_t_+1 | C1: ='ALL VARS'!G1 -> Daily Return_t | D1: ='ALL VARS'!H1 -> Daily Return_t_minus_1 | E1: ='ALL VARS'!T1 -> Sent_t_+_1_k, k=0 | F1: ='ALL VARS'!V1 -> Sent_t_+_1_k, k=0 * (VIX_10_t minus VIX_bar_10) | G1: ='ALL VARS'!J1 -> VIX_10_t
A2: ='ALL VARS'!A2 -> 43913 | B2: ='ALL VARS'!F2 -> 0.12475615 | C2: ='ALL VARS'!G2 -> 0.054244434 | D2: ='ALL VARS'!H2 -> -0.057383803 | E2: ='ALL VARS'!T2 -> -0.0049289412 | F2: ='ALL VARS'!V2 -> -0.1034609 | G2: ='ALL VARS'!J2 -> 66.205001 | I2: RAPPORT DÉTAILLÉ
A3: ='ALL VARS'!A3 -> 43910 | B3: ='ALL VARS'!F3 -> 0.054244434 | C3: ='ALL VARS'!G3 -> -0.057383803 | D3: ='ALL VARS'!H3 -> 0.045608879 | E3: ='ALL VARS'!T3 -> 0.016987293 | F3: ='ALL VARS'!V3 -> 0.31563224 | G3: ='ALL VARS'!J3 -> 63.795
A4: ='ALL VARS'!A4 -> 43909 | B4: ='ALL VARS'!F4 -> -0.057383803 | C4: ='ALL VARS'!G4 -> 0.045608879 | D4: ='ALL VARS'!H4 -> -0.090980284 | E4: ='ALL VARS'!T4 -> -0.0055165897 | F4: ='ALL VARS'!V4 -> -0.08463823 | G4: ='ALL VARS'!J4 -> 60.557 | I4: Statistiques de la régression
A5: ='ALL VARS'!A5 -> 43908 | B5: ='ALL VARS'!F5 -> 0.045608879 | C5: ='ALL VARS'!G5 -> -0.090980284 | D5: ='ALL VARS'!H5 -> 0.091896786 | E5: ='ALL VARS'!T5 -> -0.00017128678 | F5: ='ALL VARS'!V5 -> -0.001866425 | G5: ='ALL VARS'!J5 -> 56.111001 | I5: Coefficient de détermination multiple | J5: 0.81809879
A6: ='ALL VARS'!A6 -> 43907 | B6: ='ALL VARS'!F6 -> -0.090980284 | C6: ='ALL VARS'!G6 -> 0.091896786 | D6: ='ALL VARS'!H6 -> 0.026592998 | E6: ='ALL VARS'!T6 -> -0.034952246 | F6: ='ALL VARS'!V6 -> -0.24422851 | G6: ='ALL VARS'!J6 -> 52.202 | I6: Coefficient de détermination R^2 | J6: 0.66928562
A7: ='ALL VARS'!A7 -> 43906 | B7: ='ALL VARS'!F7 -> 0.091896786 | C7: ='ALL VARS'!G7 -> 0.026592998 | D7: ='ALL VARS'!H7 -> -0.035941856 | E7: ='ALL VARS'!T7 -> -0.0015805664 | F7: ='ALL VARS'!V7 -> -0.0032567426 | G7: ='ALL VARS'!J7 -> 47.275 | I7: Coefficient de détermination R^2 | J7: 0.20471412
A8: ='ALL VARS'!A8 -> 43903 | B8: ='ALL VARS'!F8 -> 0.026592998 | C8: ='ALL VARS'!G8 -> -0.035941856 | D8: ='ALL VARS'!H8 -> -0.10349444 | E8: ='ALL VARS'!T8 -> 0.00058939209 | F8: ='ALL VARS'!V8 -> 0.00017003419 | G8: ='ALL VARS'!J8 -> 45.503 | I8: Erreur-type | J8: 0.061751077
A9: ='ALL VARS'!A9 -> 43902 | B9: ='ALL VARS'!F9 -> -0.035941856 | C9: ='ALL VARS'!G9 -> -0.10349444 | D9: ='ALL VARS'!H9 -> -0.065869012 | E9: ='ALL VARS'!T9 -> -0.0055254527 | F9: ='ALL VARS'!V9 -> 0.018468877 | G9: ='ALL VARS'!J9 -> 41.872 | I9: Observations | J9: 10
A10: ='ALL VARS'!A10 -> 43901 | B10: ='ALL VARS'!F10 -> -0.10349444 | C10: ='ALL VARS'!G10 -> -0.065869012 | D10: ='ALL VARS'!H10 -> 0.013692262 | E10: ='ALL VARS'!T10 -> -0.0070630843 | F10: ='ALL VARS'!V10 -> 0.042212591 | G10: ='ALL VARS'!J10 -> 39.237999
A11: ='ALL VARS'!A11 -> 43900 | B11: ='ALL VARS'!F11 -> -0.065869012 | C11: ='ALL VARS'!G11 -> 0.013692262 | D11: ='ALL VARS'!H11 -> -0.072693785 | E11: ='ALL VARS'!T11 -> -0.00712793 | F11: ='ALL VARS'!V11 -> 0.056463965 | G11: ='ALL VARS'!J11 -> 37.293 | I11: ANALYSE DE VARIANCE
J12: Degré de liberté | K12: Somme des carrés | L12: Moyenne des carrés | M12: F | N12: Valeur critique de F
I13: Régression | J13: 5 | K13: 0.03858491 | L13: 0.007716982 | M13: 2.0237573 | N13: 0.25717633
I14: Résidus | J14: 5 | K14: 0.019065977 | L14: 0.0038131955
I15: Total | J15: 10 | K15: 0.057650887
J17: Coefficients | K17: Erreur-type | L17: Statistique t | M17: Probabilité | N17: Limite inférieure pour seuil de confiance = 95% | O17: Limite supérieure pour seuil de confiance = 95% | P17: Limite inférieure pour seuil de confiance = 95,0% | Q17: Limite supérieure pour seuil de confiance = 95,0%
I18: Constante | J18: 0 | K18: #N/A | L18: #N/A | M18: #N/A | N18: #N/A | O18: #N/A | P18: #N/A | Q18: #N/A
I19: Daily Return_t | J19: 0.32709371 | K19: 0.39115911 | L19: 0.83621654 | M19: 0.44115193 | N19: -0.67841278 | O19: 1.3326002 | P19: -0.67841278 | Q19: 1.3326002
I20: Daily Return_t_minus_1 | J20: 0.26968584 | K20: 0.32573635 | L20: 0.82792676 | M20: 0.44541717 | N20: -0.5676461 | O20: 1.1070178 | P20: -0.5676461 | Q20: 1.1070178
I21: Sent_t_+_1_k, k=0 | J21: 8.9790669 | K21: 3.0340713 | L21: 2.9594119 | M21: 0.031540314 | N21: 1.1797383 | O21: 16.778395 | P21: 1.1797383 | Q21: 16.778395
I22: Sent_t_+_1_k, k=0 * (VIX_10_t minus VIX_bar_10) | J22: -0.49774761 | K22: 0.2986806 | L22: -1.6664879 | M22: 0.15649391 | N22: -1.2655305 | O22: 0.27003532 | P22: -1.2655305 | Q22: 0.27003532
I23: VIX_10_t | J23: 0.0010356793 | K23: 0.00049320172 | L23: 2.0999101 | M23: 0.089763485 | N23: -0.00023213609 | O23: 0.0023034947 | P23: -0.00023213609 | Q23: 0.0023034947

Sheet Eq4 avec Sent__t_+_1_k, k=1
A1: ='ALL VARS'!A1 -> Date | B1: ='ALL VARS'!F1 -> Daily Return_t_+1 | C1: ='ALL VARS'!G1 -> Daily Return_t | D1: ='ALL VARS'!H1 -> Daily Return_t_minus_1 | E1: ='ALL VARS'!X1 -> Sent_t_+_1_k, k=1 | F1: ='ALL VARS'!Z1 -> Sent_t_+_1_k, k=1 * (VIX_10_t minus VIX_bar_10) | G1: ='ALL VARS'!J1 -> VIX_10_t
A2: ='ALL VARS'!A2 -> 43913 | B2: ='ALL VARS'!F2 -> 0.12475615 | C2: ='ALL VARS'!G2 -> 0.054244434 | D2: ='ALL VARS'!H2 -> -0.057383803 | E2: ='ALL VARS'!X2 -> -0.0051828275 | F2: ='ALL VARS'!Z2 -> -0.1087901 | G2: ='ALL VARS'!J2 -> 66.205001 | I2: RAPPORT DÉTAILLÉ
A3: ='ALL VARS'!A3 -> 43910 | B3: ='ALL VARS'!F3 -> 0.054244434 | C3: ='ALL VARS'!G3 -> -0.057383803 | D3: ='ALL VARS'!H3 -> 0.045608879 | E3: ='ALL VARS'!X3 -> 0.010154785 | F3: ='ALL VARS'!Z3 -> 0.18868089 | G3: ='ALL VARS'!J3 -> 63.795
A4: ='ALL VARS'!A4 -> 43909 | B4: ='ALL VARS'!F4 -> -0.057383803 | C4: ='ALL VARS'!G4 -> 0.045608879 | D4: ='ALL VARS'!H4 -> -0.090980284 | E4: ='ALL VARS'!X4 -> -0.0055161055 | F4: ='ALL VARS'!Z4 -> -0.084630801 | G4: ='ALL VARS'!J4 -> 60.557 | I4: Statistiques de la régression
A5: ='ALL VARS'!A5 -> 43908 | B5: ='ALL VARS'!F5 -> 0.045608879 | C5: ='ALL VARS'!G5 -> -0.090980284 | D5: ='ALL VARS'!H5 -> 0.091896786 | E5: ='ALL VARS'!X5 -> -0.00017128525 | F5: ='ALL VARS'!Z5 -> -0.0018664083 | G5: ='ALL VARS'!J5 -> 56.111001 | I5: Coefficient de détermination multiple | J5: 0.21299796
A6: ='ALL VARS'!A6 -> 43907 | B6: ='ALL VARS'!F6 -> -0.090980284 | C6: ='ALL VARS'!G6 -> 0.091896786 | D6: ='ALL VARS'!H6 -> 0.026592998 | E6: ='ALL VARS'!X6 -> -0.0040604122 | F6: ='ALL VARS'!Z6 -> -0.028372095 | G6: ='ALL VARS'!J6 -> 52.202 | I6: Coefficient de détermination R^2 | J6: 0.045368129
A7: ='ALL VARS'!A7 -> 43906 | B7: ='ALL VARS'!F7 -> 0.091896786 | C7: ='ALL VARS'!G7 -> 0.026592998 | D7: ='ALL VARS'!H7 -> -0.035941856 | E7: ='ALL VARS'!X7 -> -0.0091976094 | F7: ='ALL VARS'!Z7 -> -0.01895159 | G7: ='ALL VARS'!J7 -> 47.275 | I7: Coefficient de détermination R^2 | J7: -0.91833737
A8: ='ALL VARS'!A8 -> 43903 | B8: ='ALL VARS'!F8 -> 0.026592998 | C8: ='ALL VARS'!G8 -> -0.035941856 | D8: ='ALL VARS'!H8 -> -0.10349444 | E8: ='ALL VARS'!X8 -> 0.00058937332 | F8: ='ALL VARS'!Z8 -> 0.00017002877 | G8: ='ALL VARS'!J8 -> 45.503 | I8: Erreur-type | J8: 0.10491461
A9: ='ALL VARS'!A9 -> 43902 | B9: ='ALL VARS'!F9 -> -0.035941856 | C9: ='ALL VARS'!G9 -> -0.10349444 | D9: ='ALL VARS'!H9 -> -0.065869012 | E9: ='ALL VARS'!X9 -> -0.036524204 | F9: ='ALL VARS'!Z9 -> 0.12208249 | G9: ='ALL VARS'!J9 -> 41.872 | I9: Observations | J9: 10
A10: ='ALL VARS'!A10 -> 43901 | B10: ='ALL VARS'!F10 -> -0.10349444 | C10: ='ALL VARS'!G10 -> -0.065869012 | D10: ='ALL VARS'!H10 -> 0.013692262 | E10: ='ALL VARS'!X10 -> -0.0010380612 | F10: ='ALL VARS'!Z10 -> 0.0062039828 | G10: ='ALL VARS'!J10 -> 39.237999
A11: ='ALL VARS'!A11 -> 43900 | B11: ='ALL VARS'!F11 -> -0.065869012 | C11: ='ALL VARS'!G11 -> 0.013692262 | D11: ='ALL VARS'!H11 -> -0.072693785 | E11: ='ALL VARS'!X11 -> -0.00088192819 | F11: ='ALL VARS'!Z11 -> 0.0069862026 | G11: ='ALL VARS'!J11 -> 37.293 | I11: ANALYSE DE VARIANCE
J12: Degré de liberté | K12: Somme des carrés | L12: Moyenne des carrés | M12: F | N12: Valeur critique de F
I13: Régression | J13: 5 | K13: 0.0026155129 | L13: 0.00052310258 | M13: 0.047524214 | N13: 0.99749837
I14: Résidus | J14: 5 | K14: 0.055035375 | L14: 0.011007075
I15: Total | J15: 10 | K15: 0.057650887
J17: Coefficients | K17: Erreur-type | L17: Statistique t | M17: Probabilité | N17: Limite inférieure pour seuil de confiance = 95% | O17: Limite supérieure pour seuil de confiance = 95% | P17: Limite inférieure pour seuil de confiance = 95,0% | Q17: Limite supérieure pour seuil de confiance = 95,0%
I18: Constante | J18: 0 | K18: #N/A | L18: #N/A | M18: #N/A | N18: #N/A | O18: #N/A | P18: #N/A | Q18: #N/A
I19: Daily Return_t | J19: -0.12918518 | K19: 0.72004292 | L19: -0.17941317 | M19: 0.86465731 | N19: -1.9801144 | O19: 1.7217441 | P19: -1.9801144 | Q19: 1.7217441
I20: Daily Return_t_minus_1 | J20: 0.0088529429 | K20: 0.62063235 | L20: 0.014264392 | M20: 0.98917072 | N20: -1.5865333 | O20: 1.6042392 | P20: -1.5865333 | Q20: 1.6042392
I21: Sent_t_+_1_k, k=1 | J21: 1.1554737 | K21: 3.2539497 | L21: 0.35509883 | M21: 0.73700341 | N21: -7.2090703 | O21: 9.5200178 | P21: -7.2090703 | Q21: 9.5200178
I22: Sent_t_+_1_k, k=1 * (VIX_10_t minus VIX_bar_10) | J22: -0.10256206 | K22: 0.53716482 | L22: -0.19093219 | M22: 0.85608945 | N22: -1.4833882 | O22: 1.2782641 | P22: -1.4833882 | Q22: 1.2782641
I23: VIX_10_t | J23: 0.00022323567 | K23: 0.00070001491 | L23: 0.31890131 | M23: 0.76269301 | N23: -0.0015762099 | O23: 0.0020226813 | P23: -0.0015762099 | Q23: 0.0020226813

Sheet Eq4 avec Sent__t_+_1_k, k=2
A1: ='ALL VARS'!A1 -> Date | B1: ='ALL VARS'!F1 -> Daily Return_t_+1 | C1: ='ALL VARS'!G1 -> Daily Return_t | D1: ='ALL VARS'!H1 -> Daily Return_t_minus_1 | E1: ='ALL VARS'!AB1 -> Sent_t_+_1_k, k=2 | F1: ='ALL VARS'!AD1 -> Sent_t_+_1_k, k=2 * (VIX_10_t minus VIX_bar_10) | G1: ='ALL VARS'!J1 -> VIX_10_t
A2: ='ALL VARS'!A2 -> 43913 | B2: ='ALL VARS'!F2 -> 0.12475615 | C2: ='ALL VARS'!G2 -> 0.054244434 | D2: ='ALL VARS'!H2 -> -0.057383803 | E2: ='ALL VARS'!AB2 -> -0.0083667689 | F2: ='ALL VARS'!AD2 -> -0.17562259 | G2: ='ALL VARS'!J2 -> 66.205001 | I2: RAPPORT DÉTAILLÉ
A3: ='ALL VARS'!A3 -> 43910 | B3: ='ALL VARS'!F3 -> 0.054244434 | C3: ='ALL VARS'!G3 -> -0.057383803 | D3: ='ALL VARS'!H3 -> 0.045608879 | E3: ='ALL VARS'!AB3 -> 0.0017143712 | F3: ='ALL VARS'!AD3 -> 0.03185386 | G3: ='ALL VARS'!J3 -> 63.795
A4: ='ALL VARS'!A4 -> 43909 | B4: ='ALL VARS'!F4 -> -0.057383803 | C4: ='ALL VARS'!G4 -> 0.045608879 | D4: ='ALL VARS'!H4 -> -0.090980284 | E4: ='ALL VARS'!AB4 -> -0.0055161516 | F4: ='ALL VARS'!AD4 -> -0.084631508 | G4: ='ALL VARS'!J4 -> 60.557 | I4: Statistiques de la régression
A5: ='ALL VARS'!A5 -> 43908 | B5: ='ALL VARS'!F5 -> 0.045608879 | C5: ='ALL VARS'!G5 -> -0.090980284 | D5: ='ALL VARS'!H5 -> 0.091896786 | E5: ='ALL VARS'!AB5 -> -0.0017174014 | F5: ='ALL VARS'!AD5 -> -0.01871365 | G5: ='ALL VARS'!J5 -> 56.111001 | I5: Coefficient de détermination multiple | J5: 0.7303295
A6: ='ALL VARS'!A6 -> 43907 | B6: ='ALL VARS'!F6 -> -0.090980284 | C6: ='ALL VARS'!G6 -> 0.091896786 | D6: ='ALL VARS'!H6 -> 0.026592998 | E6: ='ALL VARS'!AB6 -> -0.0040605107 | F6: ='ALL VARS'!AD6 -> -0.028372783 | G6: ='ALL VARS'!J6 -> 52.202 | I6: Coefficient de détermination R^2 | J6: 0.53338117
A7: ='ALL VARS'!A7 -> 43906 | B7: ='ALL VARS'!F7 -> 0.091896786 | C7: ='ALL VARS'!G7 -> 0.026592998 | D7: ='ALL VARS'!H7 -> -0.035941856 | E7: ='ALL VARS'!AB7 -> -0.017032331 | F7: ='ALL VARS'!AD7 -> -0.035094962 | G7: ='ALL VARS'!J7 -> 47.275 | I7: Coefficient de détermination R^2 | J7: -0.039913887
A8: ='ALL VARS'!A8 -> 43903 | B8: ='ALL VARS'!F8 -> 0.026592998 | C8: ='ALL VARS'!G8 -> -0.035941856 | D8: ='ALL VARS'!H8 -> -0.10349444 | E8: ='ALL VARS'!AB8 -> 0.0076543061 | F8: ='ALL VARS'!AD8 -> 0.0022081968 | G8: ='ALL VARS'!J8 -> 45.503 | I8: Erreur-type | J8: 0.073349832
A9: ='ALL VARS'!A9 -> 43902 | B9: ='ALL VARS'!F9 -> -0.035941856 | C9: ='ALL VARS'!G9 -> -0.10349444 | D9: ='ALL VARS'!H9 -> -0.065869012 | E9: ='ALL VARS'!AB9 -> -0.035048006 | F9: ='ALL VARS'!AD9 -> 0.11714829 | G9: ='ALL VARS'!J9 -> 41.872 | I9: Observations | J9: 10
A10: ='ALL VARS'!A10 -> 43901 | B10: ='ALL VARS'!F10 -> -0.10349444 | C10: ='ALL VARS'!G10 -> -0.065869012 | D10: ='ALL VARS'!H10 -> 0.013692262 | E10: ='ALL VARS'!AB10 -> -0.012657981 | F10: ='ALL VARS'!AD10 -> 0.075650547 | G10: ='ALL VARS'!J10 -> 39.237999
A11: ='ALL VARS'!A11 -> 43900 | B11: ='ALL VARS'!F11 -> -0.065869012 | C11: ='ALL VARS'!G11 -> 0.013692262 | D11: ='ALL VARS'!H11 -> -0.072693785 | E11: ='ALL VARS'!AB11 -> -0.008637216 | F11: ='ALL VARS'!AD11 -> 0.068419789 | G11: ='ALL VARS'!J11 -> 37.293 | I11: ANALYSE DE VARIANCE
J12: Degré de liberté | K12: Somme des carrés | L12: Moyenne des carrés | M12: F | N12: Valeur critique de F
I13: Régression | J13: 5 | K13: 0.030749898 | L13: 0.0061499796 | M13: 1.1430768 | N13: 0.46134724
I14: Résidus | J14: 5 | K14: 0.026900989 | L14: 0.0053801979
I15: Total | J15: 10 | K15: 0.057650887
J17: Coefficients | K17: Erreur-type | L17: Statistique t | M17: Probabilité | N17: Limite inférieure pour seuil de confiance = 95% | O17: Limite supérieure pour seuil de confiance = 95% | P17: Limite inférieure pour seuil de confiance = 95,0% | Q17: Limite supérieure pour seuil de confiance = 95,0%
I18: Constante | J18: 0 | K18: #N/A | L18: #N/A | M18: #N/A | N18: #N/A | O18: #N/A | P18: #N/A | Q18: #N/A
I19: Daily Return_t | J19: -0.79574225 | K19: 0.51057964 | L19: -1.5585076 | M19: 0.17985221 | N19: -2.108229 | O19: 0.51674451 | P19: -2.108229 | Q19: 0.51674451
I20: Daily Return_t_minus_1 | J20: -0.034274177 | K20: 0.40017428 | L20: -0.085648125 | M20: 0.93507003 | N20: -1.0629549 | O20: 0.99440657 | P20: -1.0629549 | Q20: 0.99440657
I21: Sent_t_+_1_k, k=2 | J21: -0.27525334 | K21: 2.288115 | L21: -0.12029699 | M21: 0.90893234 | N21: -6.1570402 | O21: 5.6065335 | P21: -6.1570402 | Q21: 5.6065335
I22: Sent_t_+_1_k, k=2 * (VIX_10_t minus VIX_bar_10) | J22: -0.96639293 | K22: 0.42826979 | L22: -2.256505 | M22: 0.073673659 | N22: -2.0672955 | O22: 0.13450962 | P22: -2.0672955 | Q22: 0.13450962
I23: VIX_10_t | J23: -0.00035044664 | K23: 0.0006144072 | L23: -0.57038173 | M23: 0.59309362 | N23: -0.0019298306 | O23: 0.0012289373 | P23: -0.0019298306 | Q23: 0.0012289373

Sheet Eq4 avec Sent__t_+_1_k, k=3
A1: ='ALL VARS'!A1 -> Date | B1: ='ALL VARS'!F1 -> Daily Return_t_+1 | C1: ='ALL VARS'!G1 -> Daily Return_t | D1: ='ALL VARS'!H1 -> Daily Return_t_minus_1 | E1: ='ALL VARS'!AF1 -> Sent_t_+_1_k, k=3 | F1: ='ALL VARS'!AH1 -> Sent_t_+_1_k, k=3 * (VIX_10_t minus VIX_bar_10) | G1: ='ALL VARS'!J1 -> VIX_10_t
A2: ='ALL VARS'!A2 -> 43913 | B2: ='ALL VARS'!F2 -> 0.12475615 | C2: ='ALL VARS'!G2 -> 0.054244434 | D2: ='ALL VARS'!H2 -> -0.057383803 | E2: ='ALL VARS'!AF2 -> -0.0093807704 | F2: ='ALL VARS'!AH2 -> -0.19690698 | G2: ='ALL VARS'!J2 -> 66.205001 | I2: RAPPORT DÉTAILLÉ
A3: ='ALL VARS'!A3 -> 43910 | B3: ='ALL VARS'!F3 -> 0.054244434 | C3: ='ALL VARS'!G3 -> -0.057383803 | D3: ='ALL VARS'!H3 -> 0.045608879 | E3: ='ALL VARS'!AF3 -> 0.001714303 | F3: ='ALL VARS'!AH3 -> 0.031852592 | G3: ='ALL VARS'!J3 -> 63.795
A4: ='ALL VARS'!A4 -> 43909 | B4: ='ALL VARS'!F4 -> -0.057383803 | C4: ='ALL VARS'!G4 -> 0.045608879 | D4: ='ALL VARS'!H4 -> -0.090980284 | E4: ='ALL VARS'!AF4 -> -0.0055164069 | F4: ='ALL VARS'!AH4 -> -0.084635425 | G4: ='ALL VARS'!J4 -> 60.557 | I4: Statistiques de la régression
A5: ='ALL VARS'!A5 -> 43908 | B5: ='ALL VARS'!F5 -> 0.045608879 | C5: ='ALL VARS'!G5 -> -0.090980284 | D5: ='ALL VARS'!H5 -> 0.091896786 | E5: ='ALL VARS'!AF5 -> -0.0005472193 | F5: ='ALL VARS'!AH5 -> -0.0059627706 | G5: ='ALL VARS'!J5 -> 56.111001 | I5: Coefficient de détermination multiple | J5: 0.63136772
A6: ='ALL VARS'!A6 -> 43907 | B6: ='ALL VARS'!F6 -> -0.090980284 | C6: ='ALL VARS'!G6 -> 0.091896786 | D6: ='ALL VARS'!H6 -> 0.026592998 | E6: ='ALL VARS'!AF6 -> -0.0040604921 | F6: ='ALL VARS'!AH6 -> -0.028372653 | G6: ='ALL VARS'!J6 -> 52.202 | I6: Coefficient de détermination R^2 | J6: 0.3986252
A7: ='ALL VARS'!A7 -> 43906 | B7: ='ALL VARS'!F7 -> 0.091896786 | C7: ='ALL VARS'!G7 -> 0.026592998 | D7: ='ALL VARS'!H7 -> -0.035941856 | E7: ='ALL VARS'!AF7 -> -0.0098072255 | F7: ='ALL VARS'!AH7 -> -0.020207699 | G7: ='ALL VARS'!J7 -> 47.275 | I7: Coefficient de détermination R^2 | J7: -0.28247464
A8: ='ALL VARS'!A8 -> 43903 | B8: ='ALL VARS'!F8 -> 0.026592998 | C8: ='ALL VARS'!G8 -> -0.035941856 | D8: ='ALL VARS'!H8 -> -0.10349444 | E8: ='ALL VARS'!AF8 -> 0.00058939635 | F8: ='ALL VARS'!AH8 -> 0.00017003542 | G8: ='ALL VARS'!J8 -> 45.503 | I8: Erreur-type | J8: 0.083270392
A9: ='ALL VARS'!A9 -> 43902 | B9: ='ALL VARS'!F9 -> -0.035941856 | C9: ='ALL VARS'!G9 -> -0.10349444 | D9: ='ALL VARS'!H9 -> -0.065869012 | E9: ='ALL VARS'!AF9 -> -0.049581885 | F9: ='ALL VARS'!AH9 -> 0.16572791 | G9: ='ALL VARS'!J9 -> 41.872 | I9: Observations | J9: 10
A10: ='ALL VARS'!A10 -> 43901 | B10: ='ALL VARS'!F10 -> -0.10349444 | C10: ='ALL VARS'!G10 -> -0.065869012 | D10: ='ALL VARS'!H10 -> 0.013692262 | E10: ='ALL VARS'!AF10 -> -0.0064605697 | F10: ='ALL VARS'!AH10 -> 0.038611657 | G10: ='ALL VARS'!J10 -> 39.237999
A11: ='ALL VARS'!A11 -> 43900 | B11: ='ALL VARS'!F11 -> -0.065869012 | C11: ='ALL VARS'!G11 -> 0.013692262 | D11: ='ALL VARS'!H11 -> -0.072693785 | E11: ='ALL VARS'!AF11 -> -0.010756835 | F11: ='ALL VARS'!AH11 -> 0.085210371 | G11: ='ALL VARS'!J11 -> 37.293 | I11: ANALYSE DE VARIANCE
J12: Degré de liberté | K12: Somme des carrés | L12: Moyenne des carrés | M12: F | N12: Valeur critique de F
I13: Régression | J13: 5 | K13: 0.022981096 | L13: 0.0045962193 | M13: 0.6628565 | N13: 0.67282715
I14: Résidus | J14: 5 | K14: 0.034669791 | L14: 0.0069339582
I15: Total | J15: 10 | K15: 0.057650887
J17: Coefficients | K17: Erreur-type | L17: Statistique t | M17: Probabilité | N17: Limite inférieure pour seuil de confiance = 95% | O17: Limite supérieure pour seuil de confiance = 95% | P17: Limite inférieure pour seuil de confiance = 95,0% | Q17: Limite supérieure pour seuil de confiance = 95,0%
I18: Constante | J18: 0 | K18: #N/A | L18: #N/A | M18: #N/A | N18: #N/A | O18: #N/A | P18: #N/A | Q18: #N/A
I19: Daily Return_t | J19: -0.65295499 | K19: 0.57689003 | L19: -1.1318535 | M19: 0.3090405 | N19: -2.135898 | O19: 0.82998805 | P19: -2.135898 | Q19: 0.82998805
I20: Daily Return_t_minus_1 | J20: -0.019580631 | K20: 0.49535875 | L20: -0.039528183 | M20: 0.96999905 | N20: -1.2929408 | O20: 1.2537796 | P20: -1.2929408 | Q20: 1.2537796
I21: Sent_t_+_1_k, k=3 | J21: -0.58885096 | K21: 2.484417 | L21: -0.23701777 | M21: 0.82204783 | N21: -6.9752481 | O21: 5.7975461 | P21: -6.9752481 | Q21: 5.7975461
I22: Sent_t_+_1_k, k=3 * (VIX_10_t minus VIX_bar_10) | J22: -0.75185761 | K22: 0.44959171 | L22: -1.672312 | M22: 0.1553233 | N22: -1.9075699 | O22: 0.40385467 | P22: -1.9075699 | Q22: 0.40385467
I23: VIX_10_t | J23: -0.00027688269 | K23: 0.00068072827 | L23: -0.40674481 | M23: 0.70102143 | N23: -0.0020267504 | O23: 0.001472985 | P23: -0.0020267504 | Q23: 0.001472985

Sheet Eq4 avec Sent__t_+_1_k, k=4
A1: ='ALL VARS'!A1 -> Date | B1: ='ALL VARS'!F1 -> Daily Return_t_+1 | C1: ='ALL VARS'!G1 -> Daily Return_t | D1: ='ALL VARS'!H1 -> Daily Return_t_minus_1 | E1: ='ALL VARS'!AJ1 -> Sent_t_+_1_k, k=4 | F1: ='ALL VARS'!AL1 -> Sent_t_+_1_k, k=4 * (VIX_10_t minus VIX_bar_10) | G1: ='ALL VARS'!J1 -> VIX_10_t
A2: ='ALL VARS'!A2 -> 43913 | B2: ='ALL VARS'!F2 -> 0.12475615 | C2: ='ALL VARS'!G2 -> 0.054244434 | D2: ='ALL VARS'!H2 -> -0.057383803 | E2: ='ALL VARS'!AJ2 -> -0.009853285 | F2: ='ALL VARS'!AL2 -> -0.2068253 | G2: ='ALL VARS'!J2 -> 66.205001 | I2: RAPPORT DÉTAILLÉ
A3: ='ALL VARS'!A3 -> 43910 | B3: ='ALL VARS'!F3 -> 0.054244434 | C3: ='ALL VARS'!G3 -> -0.057383803 | D3: ='ALL VARS'!H3 -> 0.045608879 | E3: ='ALL VARS'!AJ3 -> 0.010154697 | F3: ='ALL VARS'!AL3 -> 0.18867926 | G3: ='ALL VARS'!J3 -> 63.795
A4: ='ALL VARS'!A4 -> 43909 | B4: ='ALL VARS'!F4 -> -0.057383803 | C4: ='ALL VARS'!G4 -> 0.045608879 | D4: ='ALL VARS'!H4 -> -0.090980284 | E4: ='ALL VARS'!AJ4 -> -0.03112574 | F4: ='ALL VARS'!AL4 -> -0.47754639 | G4: ='ALL VARS'!J4 -> 60.557 | I4: Statistiques de la régression
A5: ='ALL VARS'!A5 -> 43908 | B5: ='ALL VARS'!F5 -> 0.045608879 | C5: ='ALL VARS'!G5 -> -0.090980284 | D5: ='ALL VARS'!H5 -> 0.091896786 | E5: ='ALL VARS'!AJ5 -> -0.00055334375 | F5: ='ALL VARS'!AL5 -> -0.0060295055 | G5: ='ALL VARS'!J5 -> 56.111001 | I5: Coefficient de détermination multiple | J5: 0.82929064
A6: ='ALL VARS'!A6 -> 43907 | B6: ='ALL VARS'!F6 -> -0.090980284 | C6: ='ALL VARS'!G6 -> 0.091896786 | D6: ='ALL VARS'!H6 -> 0.026592998 | E6: ='ALL VARS'!AJ6 -> -0.039365742 | F6: ='ALL VARS'!AL6 -> -0.27506778 | G6: ='ALL VARS'!J6 -> 52.202 | I6: Coefficient de détermination R^2 | J6: 0.68772296
A7: ='ALL VARS'!A7 -> 43906 | B7: ='ALL VARS'!F7 -> 0.091896786 | C7: ='ALL VARS'!G7 -> 0.026592998 | D7: ='ALL VARS'!H7 -> -0.035941856 | E7: ='ALL VARS'!AJ7 -> -0.0099596077 | F7: ='ALL VARS'!AL7 -> -0.020521681 | G7: ='ALL VARS'!J7 -> 47.275 | I7: Coefficient de détermination R^2 | J7: 0.23790133
A8: ='ALL VARS'!A8 -> 43903 | B8: ='ALL VARS'!F8 -> 0.026592998 | C8: ='ALL VARS'!G8 -> -0.035941856 | D8: ='ALL VARS'!H8 -> -0.10349444 | E8: ='ALL VARS'!AJ8 -> 0.00058933216 | F8: ='ALL VARS'!AL8 -> 0.0001700169 | G8: ='ALL VARS'!J8 -> 45.503 | I8: Erreur-type | J8: 0.06000508
A9: ='ALL VARS'!A9 -> 43902 | B9: ='ALL VARS'!F9 -> -0.035941856 | C9: ='ALL VARS'!G9 -> -0.10349444 | D9: ='ALL VARS'!H9 -> -0.065869012 | E9: ='ALL VARS'!AJ9 -> -0.0055254381 | F9: ='ALL VARS'!AL9 -> 0.018468828 | G9: ='ALL VARS'!J9 -> 41.872 | I9: Observations | J9: 10
A10: ='ALL VARS'!A10 -> 43901 | B10: ='ALL VARS'!F10 -> -0.10349444 | C10: ='ALL VARS'!G10 -> -0.065869012 | D10: ='ALL VARS'!H10 -> 0.013692262 | E10: ='ALL VARS'!AJ10 -> -0.0070631412 | F10: ='ALL VARS'!AL10 -> 0.042212931 | G10: ='ALL VARS'!J10 -> 39.237999
A11: ='ALL VARS'!A11 -> 43900 | B11: ='ALL VARS'!F11 -> -0.065869012 | C11: ='ALL VARS'!G11 -> 0.013692262 | D11: ='ALL VARS'!H11 -> -0.072693785 | E11: ='ALL VARS'!AJ11 -> -0.0058305821 | F11: ='ALL VARS'!AL11 -> 0.046187011 | G11: ='ALL VARS'!J11 -> 37.293 | I11: ANALYSE DE VARIANCE
J12: Degré de liberté | K12: Somme des carrés | L12: Moyenne des carrés | M12: F | N12: Valeur critique de F
I13: Régression | J13: 5 | K13: 0.039647839 | L13: 0.0079295678 | M13: 2.2022848 | N13: 0.2321604
I14: Résidus | J14: 5 | K14: 0.018003048 | L14: 0.0036006097
I15: Total | J15: 10 | K15: 0.057650887
J17: Coefficients | K17: Erreur-type | L17: Statistique t | M17: Probabilité | N17: Limite inférieure pour seuil de confiance = 95% | O17: Limite supérieure pour seuil de confiance = 95% | P17: Limite inférieure pour seuil de confiance = 95,0% | Q17: Limite supérieure pour seuil de confiance = 95,0%
I18: Constante | J18: 0 | K18: #N/A | L18: #N/A | M18: #N/A | N18: #N/A | O18: #N/A | P18: #N/A | Q18: #N/A
I19: Daily Return_t | J19: 0.76814045 | K19: 0.42798166 | L19: 1.7947976 | M19: 0.13264306 | N19: -0.33202142 | O19: 1.8683023 | P19: -0.33202142 | Q19: 1.8683023
I20: Daily Return_t_minus_1 | J20: 0.18265025 | K20: 0.32125044 | L20: 0.56856031 | M20: 0.59423886 | N20: -0.6431503 | O20: 1.0084508 | P20: -0.6431503 | Q20: 1.0084508
I21: Sent_t_+_1_k, k=4 | J21: 8.134333 | K21: 2.6961778 | L21: 3.0169868 | M21: 0.029518121 | N21: 1.2035873 | O21: 15.065079 | P21: 1.2035873 | Q21: 15.065079
I22: Sent_t_+_1_k, k=4 * (VIX_10_t minus VIX_bar_10) | J22: -0.26425333 | K22: 0.21360277 | L22: -1.237125 | M22: 0.27097139 | N22: -0.81333672 | O22: 0.28483006 | P22: -0.81333672 | Q22: 0.28483006
I23: VIX_10_t | J23: 0.0014730283 | K23: 0.00056760376 | L23: 2.5951701 | M23: 0.048532192 | N23: 1.3956372e-05 | O23: 0.0029321002 | P23: 1.3956372e-05 | Q23: 0.0029321002

Sheet Eq4 avec Sent__t_+_1_k, k=5
A1: ='ALL VARS'!A1 -> Date | B1: ='ALL VARS'!F1 -> Daily Return_t_+1 | C1: ='ALL VARS'!G1 -> Daily Return_t | D1: ='ALL VARS'!H1 -> Daily Return_t_minus_1 | E1: ='ALL VARS'!AN1 -> Sent_t_+_1_k, k=5 | F1: ='ALL VARS'!AP1 -> Sent_t_+_1_k, k=5 * (VIX_10_t minus VIX_bar_10) | G1: ='ALL VARS'!J1 -> VIX_10_t
A2: ='ALL VARS'!A2 -> 43913 | B2: ='ALL VARS'!F2 -> 0.12475615 | C2: ='ALL VARS'!G2 -> 0.054244434 | D2: ='ALL VARS'!H2 -> -0.057383803 | E2: ='ALL VARS'!AN2 -> -0.0042560109 | F2: ='ALL VARS'!AP2 -> -0.089335762 | G2: ='ALL VARS'!J2 -> 66.205001 | I2: RAPPORT DÉTAILLÉ
A3: ='ALL VARS'!A3 -> 43910 | B3: ='ALL VARS'!F3 -> 0.054244434 | C3: ='ALL VARS'!G3 -> -0.057383803 | D3: ='ALL VARS'!H3 -> 0.045608879 | E3: ='ALL VARS'!AN3 -> 0.0017143928 | F3: ='ALL VARS'!AP3 -> 0.031854261 | G3: ='ALL VARS'!J3 -> 63.795
A4: ='ALL VARS'!A4 -> 43909 | B4: ='ALL VARS'!F4 -> -0.057383803 | C4: ='ALL VARS'!G4 -> 0.045608879 | D4: ='ALL VARS'!H4 -> -0.090980284 | E4: ='ALL VARS'!AN4 -> -0.0055163964 | F4: ='ALL VARS'!AP4 -> -0.084635264 | G4: ='ALL VARS'!J4 -> 60.557 | I4: Statistiques de la régression
A5: ='ALL VARS'!A5 -> 43908 | B5: ='ALL VARS'!F5 -> 0.045608879 | C5: ='ALL VARS'!G5 -> -0.090980284 | D5: ='ALL VARS'!H5 -> 0.091896786 | E5: ='ALL VARS'!AN5 -> -0.00085723562 | F5: ='ALL VARS'!AP5 -> -0.0093408609 | G5: ='ALL VARS'!J5 -> 56.111001 | I5: Coefficient de détermination multiple | J5: 0.50237591
A6: ='ALL VARS'!A6 -> 43907 | B6: ='ALL VARS'!F6 -> -0.090980284 | C6: ='ALL VARS'!G6 -> 0.091896786 | D6: ='ALL VARS'!H6 -> 0.026592998 | E6: ='ALL VARS'!AN6 -> -0.0040604791 | F6: ='ALL VARS'!AP6 -> -0.028372562 | G6: ='ALL VARS'!J6 -> 52.202 | I6: Coefficient de détermination R^2 | J6: 0.25238155
A7: ='ALL VARS'!A7 -> 43906 | B7: ='ALL VARS'!F7 -> 0.091896786 | C7: ='ALL VARS'!G7 -> 0.026592998 | D7: ='ALL VARS'!H7 -> -0.035941856 | E7: ='ALL VARS'!AN7 -> -0.016797308 | F7: ='ALL VARS'!AP7 -> -0.034610701 | G7: ='ALL VARS'!J7 -> 47.275 | I7: Coefficient de détermination R^2 | J7: -0.54571321
A8: ='ALL VARS'!A8 -> 43903 | B8: ='ALL VARS'!F8 -> 0.026592998 | C8: ='ALL VARS'!G8 -> -0.035941856 | D8: ='ALL VARS'!H8 -> -0.10349444 | E8: ='ALL VARS'!AN8 -> 0.00058935239 | F8: ='ALL VARS'!AP8 -> 0.00017002274 | G8: ='ALL VARS'!J8 -> 45.503 | I8: Erreur-type | J8: 0.092844889
A9: ='ALL VARS'!A9 -> 43902 | B9: ='ALL VARS'!F9 -> -0.035941856 | C9: ='ALL VARS'!G9 -> -0.10349444 | D9: ='ALL VARS'!H9 -> -0.065869012 | E9: ='ALL VARS'!AN9 -> -0.0055255973 | F9: ='ALL VARS'!AP9 -> 0.018469361 | G9: ='ALL VARS'!J9 -> 41.872 | I9: Observations | J9: 10
A10: ='ALL VARS'!A10 -> 43901 | B10: ='ALL VARS'!F10 -> -0.10349444 | C10: ='ALL VARS'!G10 -> -0.065869012 | D10: ='ALL VARS'!H10 -> 0.013692262 | E10: ='ALL VARS'!AN10 -> -0.0069688562 | F10: ='ALL VARS'!AP10 -> 0.041649436 | G10: ='ALL VARS'!J10 -> 39.237999
A11: ='ALL VARS'!A11 -> 43900 | B11: ='ALL VARS'!F11 -> -0.065869012 | C11: ='ALL VARS'!G11 -> 0.013692262 | D11: ='ALL VARS'!H11 -> -0.072693785 | E11: ='ALL VARS'!AN11 -> -0.00088197054 | F11: ='ALL VARS'!AP11 -> 0.0069865381 | G11: ='ALL VARS'!J11 -> 37.293 | I11: ANALYSE DE VARIANCE
J12: Degré de liberté | K12: Somme des carrés | L12: Moyenne des carrés | M12: F | N12: Valeur critique de F
I13: Régression | J13: 5 | K13: 0.01455002 | L13: 0.0029100041 | M13: 0.33758069 | N13: 0.86768742
I14: Résidus | J14: 5 | K14: 0.043100867 | L14: 0.0086201734
I15: Total | J15: 10 | K15: 0.057650887
J17: Coefficients | K17: Erreur-type | L17: Statistique t | M17: Probabilité | N17: Limite inférieure pour seuil de confiance = 95% | O17: Limite supérieure pour seuil de confiance = 95% | P17: Limite inférieure pour seuil de confiance = 95,0% | Q17: Limite supérieure pour seuil de confiance = 95,0%
I18: Constante | J18: 0 | K18: #N/A | L18: #N/A | M18: #N/A | N18: #N/A | O18: #N/A | P18: #N/A | Q18: #N/A
I19: Daily Return_t | J19: -0.58156603 | K19: 0.6752428 | L19: -0.8612695 | M19: 0.42845023 | N19: -2.3173329 | O19: 1.1542008 | P19: -2.3173329 | Q19: 1.1542008
I20: Daily Return_t_minus_1 | J20: 0.23933913 | K20: 0.49742942 | L20: 0.48115194 | M20: 0.65072617 | N20: -1.0393439 | O20: 1.5180222 | P20: -1.0393439 | Q20: 1.5180222
I21: Sent_t_+_1_k, k=5 | J21: 0.010703876 | K21: 5.8250003 | L21: 0.0018375753 | M21: 0.99860489 | N21: -14.962936 | O21: 14.984344 | P21: -14.962936 | Q21: 14.984344
I22: Sent_t_+_1_k, k=5 * (VIX_10_t minus VIX_bar_10) | J22: -1.3805767 | K22: 1.095385 | L22: -1.2603575 | M22: 0.26315882 | N22: -4.1963534 | O22: 1.4352 | P22: -4.1963534 | Q22: 1.4352
I23: VIX_10_t | J23: -0.00037208454 | K23: 0.00085022984 | L23: -0.43762818 | M23: 0.67991392 | N23: -0.0025576699 | O23: 0.0018135009 | P23: -0.0025576699 | Q23: 0.0018135009

Sheet Eq4 avec Sent__t_+_1_k, k=6
A1: ='ALL VARS'!A1 -> Date | B1: ='ALL VARS'!F1 -> Daily Return_t_+1 | C1: ='ALL VARS'!G1 -> Daily Return_t | D1: ='ALL VARS'!H1 -> Daily Return_t_minus_1 | E1: ='ALL VARS'!AR1 -> Sent_t_+_1_k, k=6 | F1: ='ALL VARS'!AT1 -> Sent_t_+_1_k, k=6 * (VIX_10_t minus VIX_bar_10) | G1: ='ALL VARS'!J1 -> VIX_10_t
A2: ='ALL VARS'!A2 -> 43913 | B2: ='ALL VARS'!F2 -> 0.12475615 | C2: ='ALL VARS'!G2 -> 0.054244434 | D2: ='ALL VARS'!H2 -> -0.057383803 | E2: ='ALL VARS'!AR2 -> -0.012885692 | F2: ='ALL VARS'!AT2 -> -0.27047702 | G2: ='ALL VARS'!J2 -> 66.205001 | I2: RAPPORT DÉTAILLÉ
A3: ='ALL VARS'!A3 -> 43910 | B3: ='ALL VARS'!F3 -> 0.054244434 | C3: ='ALL VARS'!G3 -> -0.057383803 | D3: ='ALL VARS'!H3 -> 0.045608879 | E3: ='ALL VARS'!AR3 -> 0.0017143413 | F3: ='ALL VARS'!AT3 -> 0.031853305 | G3: ='ALL VARS'!J3 -> 63.795
A4: ='ALL VARS'!A4 -> 43909 | B4: ='ALL VARS'!F4 -> -0.057383803 | C4: ='ALL VARS'!G4 -> 0.045608879 | D4: ='ALL VARS'!H4 -> -0.090980284 | E4: ='ALL VARS'!AR4 -> -0.07624635 | F4: ='ALL VARS'!AT4 -> -1.169809 | G4: ='ALL VARS'!J4 -> 60.557 | I4: Statistiques de la régression
A5: ='ALL VARS'!A5 -> 43908 | B5: ='ALL VARS'!F5 -> 0.045608879 | C5: ='ALL VARS'!G5 -> -0.090980284 | D5: ='ALL VARS'!H5 -> 0.091896786 | E5: ='ALL VARS'!AR5 -> -0.00097158339 | F5: ='ALL VARS'!AT5 -> -0.01058685 | G5: ='ALL VARS'!J5 -> 56.111001 | I5: Coefficient de détermination multiple | J5: 0.43844723
A6: ='ALL VARS'!A6 -> 43907 | B6: ='ALL VARS'!F6 -> -0.090980284 | C6: ='ALL VARS'!G6 -> 0.091896786 | D6: ='ALL VARS'!H6 -> 0.026592998 | E6: ='ALL VARS'!AR6 -> -0.0040606006 | F6: ='ALL VARS'!AT6 -> -0.028373411 | G6: ='ALL VARS'!J6 -> 52.202 | I6: Coefficient de détermination R^2 | J6: 0.19223598
A7: ='ALL VARS'!A7 -> 43906 | B7: ='ALL VARS'!F7 -> 0.091896786 | C7: ='ALL VARS'!G7 -> 0.026592998 | D7: ='ALL VARS'!H7 -> -0.035941856 | E7: ='ALL VARS'!AR7 -> -0.0038836146 | F7: ='ALL VARS'!AT7 -> -0.0080021524 | G7: ='ALL VARS'!J7 -> 47.275 | I7: Coefficient de détermination R^2 | J7: -0.65397524
A8: ='ALL VARS'!A8 -> 43903 | B8: ='ALL VARS'!F8 -> 0.026592998 | C8: ='ALL VARS'!G8 -> -0.035941856 | D8: ='ALL VARS'!H8 -> -0.10349444 | E8: ='ALL VARS'!AR8 -> 0.0043877431 | F8: ='ALL VARS'!AT8 -> 0.0012658235 | G8: ='ALL VARS'!J8 -> 45.503 | I8: Erreur-type | J8: 0.096507319
A9: ='ALL VARS'!A9 -> 43902 | B9: ='ALL VARS'!F9 -> -0.035941856 | C9: ='ALL VARS'!G9 -> -0.10349444 | D9: ='ALL VARS'!H9 -> -0.065869012 | E9: ='ALL VARS'!AR9 -> -0.03027812 | F9: ='ALL VARS'!AT9 -> 0.1012049 | G9: ='ALL VARS'!J9 -> 41.872 | I9: Observations | J9: 10
A10: ='ALL VARS'!A10 -> 43901 | B10: ='ALL VARS'!F10 -> -0.10349444 | C10: ='ALL VARS'!G10 -> -0.065869012 | D10: ='ALL VARS'!H10 -> 0.013692262 | E10: ='ALL VARS'!AR10 -> -0.0010381496 | F10: ='ALL VARS'!AT10 -> 0.0062045111 | G10: ='ALL VARS'!J10 -> 39.237999
A11: ='ALL VARS'!A11 -> 43900 | B11: ='ALL VARS'!F11 -> -0.065869012 | C11: ='ALL VARS'!G11 -> 0.013692262 | D11: ='ALL VARS'!H11 -> -0.072693785 | E11: ='ALL VARS'!AR11 -> -0.0055948988 | F11: ='ALL VARS'!AT11 -> 0.044320044 | G11: ='ALL VARS'!J11 -> 37.293 | I11: ANALYSE DE VARIANCE
J12: Degré de liberté | K12: Somme des carrés | L12: Moyenne des carrés | M12: F | N12: Valeur critique de F
I13: Régression | J13: 5 | K13: 0.011082575 | L13: 0.0022165149 | M13: 0.23798531 | N13: 0.9263298
I14: Résidus | J14: 5 | K14: 0.046568313 | L14: 0.0093136626
I15: Total | J15: 10 | K15: 0.057650887
J17: Coefficients | K17: Erreur-type | L17: Statistique t | M17: Probabilité | N17: Limite inférieure pour seuil de confiance = 95% | O17: Limite supérieure pour seuil de confiance = 95% | P17: Limite inférieure pour seuil de confiance = 95,0% | Q17: Limite supérieure pour seuil de confiance = 95,0%
I18: Constante | J18: 0 | K18: #N/A | L18: #N/A | M18: #N/A | N18: #N/A | O18: #N/A | P18: #N/A | Q18: #N/A
I19: Daily Return_t | J19: -0.1528702 | K19: 0.58980597 | L19: -0.25918727 | M19: 0.80582344 | N19: -1.6690147 | O19: 1.3632743 | P19: -1.6690147 | Q19: 1.3632743
I20: Daily Return_t_minus_1 | J20: -0.19701369 | K20: 0.57176082 | L20: -0.34457361 | M20: 0.74443508 | N20: -1.6667717 | O20: 1.2727443 | P20: -1.6667717 | Q20: 1.2727443
I21: Sent_t_+_1_k, k=6 | J21: 3.1242488 | K21: 3.2041288 | L21: 0.97506967 | M21: 0.37430775 | N21: -5.1122265 | O21: 11.360724 | P21: -5.1122265 | Q21: 11.360724
I22: Sent_t_+_1_k, k=6 * (VIX_10_t minus VIX_bar_10) | J22: -0.14187827 | K22: 0.21211879 | L22: -0.66886232 | M22: 0.53321912 | N22: -0.68714698 | O22: 0.40339045 | P22: -0.68714698 | Q22: 0.40339045
I23: VIX_10_t | J23: 0.0004153629 | K23: 0.00070701688 | L23: 0.58748654 | M23: 0.58240441 | N23: -0.0014020818 | O23: 0.0022328076 | P23: -0.0014020818 | Q23: 0.0022328076

Sheet Eq4 avec Sent__t_+_1_k, k=7
A1: ='ALL VARS'!A1 -> Date | B1: ='ALL VARS'!F1 -> Daily Return_t_+1 | C1: ='ALL VARS'!G1 -> Daily Return_t | D1: ='ALL VARS'!H1 -> Daily Return_t_minus_1 | E1: ='ALL VARS'!AV1 -> Sent_t_+_1_k, k=7 | F1: ='ALL VARS'!AX1 -> Sent_t_+_1_k, k=7 * (VIX_10_t minus VIX_bar_10) | G1: ='ALL VARS'!J1 -> VIX_10_t
A2: ='ALL VARS'!A2 -> 43913 | B2: ='ALL VARS'!F2 -> 0.12475615 | C2: ='ALL VARS'!G2 -> 0.054244434 | D2: ='ALL VARS'!H2 -> -0.057383803 | E2: ='ALL VARS'!AV2 -> -0.026128404 | F2: ='ALL VARS'!AX2 -> -0.54844805 | G2: ='ALL VARS'!J2 -> 66.205001 | I2: RAPPORT DÉTAILLÉ
A3: ='ALL VARS'!A3 -> 43910 | B3: ='ALL VARS'!F3 -> 0.054244434 | C3: ='ALL VARS'!G3 -> -0.057383803 | D3: ='ALL VARS'!H3 -> 0.045608879 | E3: ='ALL VARS'!AV3 -> 0.019058173 | F3: ='ALL VARS'!AX3 -> 0.35411023 | G3: ='ALL VARS'!J3 -> 63.795
A4: ='ALL VARS'!A4 -> 43909 | B4: ='ALL VARS'!F4 -> -0.057383803 | C4: ='ALL VARS'!G4 -> 0.045608879 | D4: ='ALL VARS'!H4 -> -0.090980284 | E4: ='ALL VARS'!AV4 -> -0.030603371 | F4: ='ALL VARS'!AX4 -> -0.46953195 | G4: ='ALL VARS'!J4 -> 60.557 | I4: Statistiques de la régression
A5: ='ALL VARS'!A5 -> 43908 | B5: ='ALL VARS'!F5 -> 0.045608879 | C5: ='ALL VARS'!G5 -> -0.090980284 | D5: ='ALL VARS'!H5 -> 0.091896786 | E5: ='ALL VARS'!AV5 -> -0.0030150896 | F5: ='ALL VARS'!AX5 -> -0.032853898 | G5: ='ALL VARS'!J5 -> 56.111001 | I5: Coefficient de détermination multiple | J5: 0.43881599
A6: ='ALL VARS'!A6 -> 43907 | B6: ='ALL VARS'!F6 -> -0.090980284 | C6: ='ALL VARS'!G6 -> 0.091896786 | D6: ='ALL VARS'!H6 -> 0.026592998 | E6: ='ALL VARS'!AV6 -> -0.072317029 | F6: ='ALL VARS'!AX6 -> -0.50531461 | G6: ='ALL VARS'!J6 -> 52.202 | I6: Coefficient de détermination R^2 | J6: 0.19255947
A7: ='ALL VARS'!A7 -> 43906 | B7: ='ALL VARS'!F7 -> 0.091896786 | C7: ='ALL VARS'!G7 -> 0.026592998 | D7: ='ALL VARS'!H7 -> -0.035941856 | E7: ='ALL VARS'!AV7 -> -0.025701973 | F7: ='ALL VARS'!AX7 -> -0.05295868 | G7: ='ALL VARS'!J7 -> 47.275 | I7: Coefficient de détermination R^2 | J7: -0.65339296
A8: ='ALL VARS'!A8 -> 43903 | B8: ='ALL VARS'!F8 -> 0.026592998 | C8: ='ALL VARS'!G8 -> -0.035941856 | D8: ='ALL VARS'!H8 -> -0.10349444 | E8: ='ALL VARS'!AV8 -> 0.0082946416 | F8: ='ALL VARS'!AX8 -> 0.0023929277 | G8: ='ALL VARS'!J8 -> 45.503 | I8: Erreur-type | J8: 0.096487992
A9: ='ALL VARS'!A9 -> 43902 | B9: ='ALL VARS'!F9 -> -0.035941856 | C9: ='ALL VARS'!G9 -> -0.10349444 | D9: ='ALL VARS'!H9 -> -0.065869012 | E9: ='ALL VARS'!AV9 -> -0.10358094 | F9: ='ALL VARS'!AX9 -> 0.34622025 | G9: ='ALL VARS'!J9 -> 41.872 | I9: Observations | J9: 10
A10: ='ALL VARS'!A10 -> 43901 | B10: ='ALL VARS'!F10 -> -0.10349444 | C10: ='ALL VARS'!G10 -> -0.065869012 | D10: ='ALL VARS'!H10 -> 0.013692262 | E10: ='ALL VARS'!AV10 -> -0.018066302 | F10: ='ALL VARS'!AX10 -> 0.10797343 | G10: ='ALL VARS'!J10 -> 39.237999
A11: ='ALL VARS'!A11 -> 43900 | B11: ='ALL VARS'!F11 -> -0.065869012 | C11: ='ALL VARS'!G11 -> 0.013692262 | D11: ='ALL VARS'!H11 -> -0.072693785 | E11: ='ALL VARS'!AV11 -> -0.0092237513 | F11: ='ALL VARS'!AX11 -> 0.073066034 | G11: ='ALL VARS'!J11 -> 37.293 | I11: ANALYSE DE VARIANCE
