Workbook
Name E44ct2: 'Eq7 avec Sent__t_k, k=0'!$E$44

Sheet ALL VARS
A1: Date | B1: Adj close price | C1: Daily Return-Adj | D1: Daily_aggregate_sentiment | F1: Daily Return-Adj_t_+1 | G1: Daily Return-Adj_t | H1: Daily Return-Adj_t_minus_1 | I1: Daily aggregate sentiment_t+1 | J1: VIX_10_t | K1: VIX_bar_10 | L1: VIX_10_t minus VIX_bar_10 | M1: Sent_t | N1: ck | O1: ck | P1: Sent_t_+_1 | Q1: Sent_t * (VIX_10_t minus VIX_bar_10) | R1: Sent_t_+_1 * (VIX_10_t minus VIX_bar_10) | S1: Sent_t_k, k=0 | T1: Sent_t_+_1_k, k=0 | U1: Sent_t_k, k=0 * (VIX_10_t minus VIX_bar_10) | V1: Sent_t_+_1_k, k=0 * (VIX_10_t minus VIX_bar_10) | W1: Sent_t_k, k=1 | X1: Sent_t_+_1_k, k=1 | Y1: Sent_t_k, k=1 * (VIX_10_t minus VIX_bar_10) | Z1: Sent_t_+_1_k, k=1 * (VIX_10_t minus VIX_bar_10) | AA1: Sent_t_k, k=2 | AB1: Sent_t_+_1_k, k=2 | AC1: Sent_t_k, k=2 * (VIX_10_t minus VIX_bar_10) | AD1: Sent_t_+_1_k, k=2 * (VIX_10_t minus VIX_bar_10) | AE1: Sent_t_k, k=3 | AF1: Sent_t_+_1_k, k=3 | AG1: Sent_t_k, k=3 * (VIX_10_t minus VIX_bar_10) | AH1: Sent_t_+_1_k, k=3 * (VIX_10_t minus VIX_bar_10) | AI1: Sent_t_k, k=4 | AJ1: Sent_t_+_1_k, k=4 | AK1: Sent_t_k, k=4 * (VIX_10_t minus VIX_bar_10) | AL1: Sent_t_+_1_k, k=4 * (VIX_10_t minus VIX_bar_10) | AM1: Sent_t_k, k=5 | AN1: Sent_t_+_1_k, k=5 | AO1: Sent_t_k, k=5 * (VIX_10_t minus VIX_bar_10) | AP1: Sent_t_+_1_k, k=5 * (VIX_10_t minus VIX_bar_10) | AQ1: Sent_t_k, k=6 | AR1: Sent_t_+_1_k, k=6 | AS1: Sent_t_k, k=6 * (VIX_10_t minus VIX_bar_10) | AT1: Sent_t_+_1_k, k=6 * (VIX_10_t minus VIX_bar_10) | AU1: Sent_t_k, k=7 | AV1: Sent_t_+_1_k, k=7 | AW1: Sent_t_k, k=7 * (VIX_10_t minus VIX_bar_10) | AX1: Sent_t_+_1_k, k=7 * (VIX_10_t minus VIX_bar_10) | AY1: Sent_t_k, k=8 | AZ1: Sent_t_+_1_k, k=8 | BA1: Sent_t_k, k=8 * (VIX_10_t minus VIX_bar_10) | BB1: Sent_t_+_1_k, k=8 * (VIX_10_t minus VIX_bar_10) | BC1: Sent_t_k, k=9 | BD1: Sent_t_+_1_k, k=9 | BE1: Sent_t_k, k=9 * (VIX_10_t minus VIX_bar_10) | BF1: Sent_t_+_1_k, k=9 * (VIX_10_t minus VIX_bar_10) | BH1: Sent_t | BI1: Sent_t * (VIX_10_t minus VIX_bar_10) | BJ1: Sent_t_k, k=0 | BK1: Sent_t_k, k=0 * (VIX_10_t minus VIX_bar_10) | BL1: Sent_t_k, k=1 | BM1: Sent_t_k, k=1 * (VIX_10_t minus VIX_bar_10) | BN1: Sent_t_k, k=2 | BO1: Sent_t_k, k=2 * (VIX_10_t minus VIX_bar_10) | BP1: Sent_t_k, k=3 | BQ1: Sent_t_k, k=3 * (VIX_10_t minus VIX_bar_10) | BR1: Sent_t_k, k=4 | BS1: Sent_t_k, k=4 * (VIX_10_t minus VIX_bar_10) | BT1: Sent_t_k, k=5 | BU1: Sent_t_k, k=5 * (VIX_10_t minus VIX_bar_10) | BV1: Sent_t_k, k=6 | BW1: Sent_t_k, k=6 * (VIX_10_t minus VIX_bar_10) | BX1: Sent_t_k, k=7 | BY1: Sent_t_k, k=7 * (VIX_10_t minus VIX_bar_10) | BZ1: Sent_t_k, k=8 | CA1: Sent_t_k, k=8 * (VIX_10_t minus VIX_bar_10) | CB1: Sent_t_k, k=9 | CC1: Sent_t_k, k=9 * (VIX_10_t minus VIX_bar_10) | CD1: VIX_10_t | CE1: ck
A2: 43980 | B2: 15192.8 | C2: -0.0045798181 | D2: -0.24457772 | F2: 0.02309392 | G2: -0.0045798181 | H2: -0.0006089448 | I2: -0.24457772 | J2: 29.423 | K2: 45.214509 | L2: -15.791509 | M2: -0.24457772 | N2: TRUE | O2: TRUE | P2: -0.067721572 | Q2: 3.8622512 | R2: -0.85012213 | S2: -0.040665115 | T2: -0.0016831778 | U2: 0.64216351 | V2: 0.026579917 | W2: -0.0039796702 | X2: -0.00048347977 | Y2: 0.062844997 | Z2: 0.0076348751 | AA2: -0.0039797237 | AB2: -0.002675892 | AC2: 0.062845841 | AD2: 0.042256372 | AE2: -0.0039798218 | AF2: -0.0023405862 | AG2: 0.06284739 | AH2: 0.036961387 | AI2: -0.079551947 | AJ2: -0.006288242 | AK2: 1.2562453 | AL2: 0.099300829 | AM2: -0.038919147 | AN2: -0.0063397233 | AO2: 0.61459206 | AP2: 0.1001138 | AQ2: -0.037948598 | AR2: -0.010995213 | AS2: 0.59926561 | AT2: 0.17363101 | AU2: -0.027594733 | AV2: -0.018403209 | AW2: 0.43576247 | AX2: 0.29061444 | AY2: -0.0039793149 | AZ2: -0.013136615 | BA2: 0.062839386 | BB2: 0.20744698 | BC2: -0.003979652 | BD2: -0.0053754327 | BE2: 0.06284471 | BF2: 0.084886193 | BH2: -0.24457772 | BI2: 3.8622512 | BJ2: -0.040665115 | BK2: 0.64216351 | BL2: -0.0039796702 | BM2: 0.062844997 | BN2: -0.0039797237 | BO2: 0.062845841 | BP2: -0.0039798218 | BQ2: 0.06284739 | BR2: -0.079551947 | BS2: 1.2562453 | BT2: -0.038919147 | BU2: 0.61459206 | BV2: -0.037948598 | BW2: 0.59926561 | BX2: -0.027594733 | BY2: 0.43576247 | BZ2: -0.0039793149 | CA2: 0.062839386 | CB2: -0.003979652 | CC2: 0.06284471 | CD2: 29.423 | CE2: TRUE
A3: 43979 | B3: 15262.7 | C3: -0.0006089448 | D3: 0.0062640198 | F3: -0.0045798181 | G3: -0.0006089448 | H3: 0.0081792696 | I3: 0.0062640198 | J3: 30.092 | K3: 45.214509 | L3: -15.122509 | M3: 0.0062640198 | N3: TRUE | O3: TRUE | P3: -0.24457772 | Q3: -0.094727695 | R3: 3.6986288 | S3: 0.00013925055 | T3: -0.040665115 | U3: -0.0021058177 | V3: 0.61495856 | W3: 0.0001392067 | X3: -0.0039796702 | Y3: -0.0021051545 | Z3: 0.060182598 | AA3: 0.0001392248 | AB3: -0.0039797237 | AC3: -0.0021054283 | AD3: 0.060183407 | AE3: 0.00013921647 | AF3: -0.0039798218 | AG3: -0.0021053023 | AH3: 0.06018489 | AI3: 0.0018791543 | AJ3: -0.079551947 | AK3: -0.028417528 | AL3: 1.203025 | AM3: 0.0001392224 | AN3: -0.038919147 | AO3: -0.002105392 | AP3: 0.58855515 | AQ3: 0.00013921326 | AR3: -0.037948598 | AS3: -0.0021052537 | AT3: 0.57387801 | AU3: 0.0018791681 | AV3: -0.027594733 | AW3: -0.028417736 | AX3: 0.41730159 | AY3: 0.0015311549 | AZ3: -0.0039793149 | BA3: -0.023154903 | BB3: 0.060177224 | BC3: 0.0001392083 | BD3: -0.003979652 | BE3: -0.0021051787 | BF3: 0.060182323 | BH3: 0.0062640198 | BI3: -0.094727695 | BJ3: 0.00013925055 | BK3: -0.0021058177 | BL3: 0.0001392067 | BM3: -0.0021051545 | BN3: 0.0001392248 | BO3: -0.0021054283 | BP3: 0.00013921647 | BQ3: -0.0021053023 | BR3: 0.0018791543 | BS3: -0.028417528 | BT3: 0.0001392224 | BU3: -0.002105392 | BV3: 0.00013921326 | BW3: -0.0021052537 | BX3: 0.0018791681 | BY3: -0.028417736 | BZ3: 0.0015311549 | CA3: -0.023154903 | CB3: 0.0001392083 | CC3: -0.0021051787 | CD3: 30.092 | CE3: TRUE
A4: 43978 | B4: 15272 | C4: 0.0081792696 | D4: -0.23609327 | F4: -0.0006089448 | G4: 0.0081792696 | H4: 0.0048223739 | I4: -0.23609327 | J4: 30.634 | K4: 45.214509 | L4: -14.580509 | M4: -0.23609327 | N4: TRUE | O4: TRUE | P4: 0.0062640198 | Q4: 3.44236 | R4: -0.091332596 | S4: -0.0035602667 | T4: 0.00013925055 | U4: 0.0519105 | V4: -0.0020303439 | W4: -0.003560953 | X4: 0.0001392067 | Y4: 0.051920506 | Z4: -0.0020297045 | AA4: -0.0035611298 | AB4: 0.0001392248 | AC4: 0.051923085 | AD4: -0.0020299684 | AE4: -0.0035606155 | AF4: 0.00013921647 | AG4: 0.051915586 | AH4: -0.002029847 | AI4: -0.071014121 | AJ4: 0.0018791543 | AK4: 1.035422 | AL4: -0.027399027 | AM4: -0.0035611198 | AN4: 0.0001392224 | AO4: 0.051922939 | AP4: -0.0020299334 | AQ4: -0.069139851 | AR4: 0.00013921326 | AS4: 1.0080942 | AT4: -0.0020298002 | AU4: -0.071014753 | AV4: 0.0018791681 | AW4: 1.0354312 | AX4: -0.027399227 | AY4: -0.0035602383 | AZ4: 0.0015311549 | BA4: 0.051910086 | BB4: -0.022325017 | BC4: -0.0035602187 | BD4: 0.0001392083 | BE4: 0.0519098 | BF4: -0.0020297278 | BH4: -0.23609327 | BI4: 3.44236 | BJ4: -0.0035602667 | BK4: 0.0519105 | BL4: -0.003560953 | BM4: 0.051920506 | BN4: -0.0035611298 | BO4: 0.051923085 | BP4: -0.0035606155 | BQ4: 0.051915586 | BR4: -0.071014121 | BS4: 1.035422 | BT4: -0.0035611198 | BU4: 0.051922939 | BV4: -0.069139851 | BW4: 1.0080942 | BX4: -0.071014753 | BY4: 1.0354312 | BZ4: -0.0035602383 | CA4: 0.051910086 | CB4: -0.0035602187 | CC4: 0.0519098 | CD4: 30.634 | CE4: TRUE
A5: 43977 | B5: 15148.1 | C5: 0.0048223739 | D5: 0.13119693 | F5: 0.0081792696 | G5: 0.0048223739 | H5: 0.010849211 | I5: 0.13119693 | J5: 30.59 | K5: 45.214509 | L5: -14.624509 | M5: 0.13119693 | N5: TRUE | O5: TRUE | P5: -0.23609327 | Q5: -1.9186907 | R5: 3.4527481 | S5: 0.0022716123 | T5: -0.0035602667 | U5: -0.033221214 | V5: 0.052067151 | W5: 0.0022717113 | X5: -0.003560953 | Y5: -0.033222663 | Z5: 0.052077188 | AA5: 0.00227159 | AB5: -0.0035611298 | AC5: -0.033220888 | AD5: 0.052079775 | AE5: 0.018336339 | AF5: -0.0035606155 | AG5: -0.26815996 | AH5: 0.052072253 | AI5: 0.0022719341 | AJ5: -0.071014121 | AK5: -0.03322592 | AL5: 1.0385467 | AM5: 0.017890036 | AN5: -0.0035611198 | AO5: -0.26163299 | AP5: 0.052079629 | AQ5: 0.017890084 | AR5: -0.069139851 | AS5: -0.2616337 | AT5: 1.0111364 | AU5: 0.06061344 | AV5: -0.071014753 | AW5: -0.88644179 | AX5: 1.0385559 | AY5: 0.0022715361 | AZ5: -0.0035602383 | BA5: -0.0332201 | BB5: 0.052066736 | BC5: 0.0051086518 | BD5: -0.0035602187 | BE5: -0.074711523 | BF5: 0.05206645 | BH5: 0.13119693 | BI5: -1.9186907 | BJ5: 0.0022716123 | BK5: -0.033221214 | BL5: 0.0022717113 | BM5: -0.033222663 | BN5: 0.00227159 | BO5: -0.033220888 | BP5: 0.018336339 | BQ5: -0.26815996 | BR5: 0.0022719341 | BS5: -0.03322592 | BT5: 0.017890036 | BU5: -0.26163299 | BV5: 0.017890084 | BW5: -0.2616337 | BX5: 0.06061344 | BY5: -0.88644179 | BZ5: 0.0022715361 | CA5: -0.0332201 | CB5: 0.0051086518 | CC5: -0.074711523 | CD5: 30.59 | CE5: TRUE
A6: 43976 | B6: 15075.4 | C6: 0.010849211 | D6: -0.66873623 | F6: 0.0048223739 | G6: 0.010849211 | H6: 0.0019280759 | I6: -0.66873623 | J6: 30.581 | K6: 45.214509 | L6: -14.633509 | M6: -0.66873623 | N6: TRUE | O6: TRUE | P6: 0.13119693 | Q6: 9.7859577 | R6: -1.9198715 | S6: -0.011965292 | T6: 0.0022716123 | U6: 0.1750942 | V6: -0.033241659 | W6: -0.011963391 | X6: 0.0022717113 | Y6: 0.17506638 | Z6: -0.033243108 | AA6: -0.011966886 | AB6: 0.00227159 | AC6: 0.17511754 | AD6: -0.033241332 | AE6: -0.011964713 | AF6: 0.018336339 | AG6: 0.17508574 | AH6: -0.26832499 | AI6: -0.011964591 | AJ6: 0.0022719341 | AK6: 0.17508395 | AL6: -0.033246367 | AM6: -0.14429407 | AN6: 0.017890036 | AO6: 2.1115286 | AP6: -0.261794 | AQ6: -0.011963966 | AR6: 0.017890084 | AS6: 0.1750748 | AT6: -0.26179471 | AU6: -0.22142565 | AV6: 0.06061344 | AW6: 3.2402343 | AX6: -0.88698731 | AY6: -0.2192633 | AZ6: 0.0022715361 | BA6: 3.2085914 | BB6: -0.033240544 | BC6: -0.011964376 | BD6: 0.0051086518 | BE6: 0.1750808 | BF6: -0.074757501 | BH6: -0.66873623 | BI6: 9.7859577 | BJ6: -0.011965292 | BK6: 0.1750942 | BL6: -0.011963391 | BM6: 0.17506638 | BN6: -0.011966886 | BO6: 0.17511754 | BP6: -0.011964713 | BQ6: 0.17508574 | BR6: -0.011964591 | BS6: 0.17508395 | BT6: -0.14429407 | BU6: 2.1115286 | BV6: -0.011963966 | BW6: 0.1750748 | BX6: -0.22142565 | BY6: 3.2402343 | BZ6: -0.2192633 | CA6: 3.2085914 | CB6: -0.011964376 | CC6: 0.1750808 | CD6: 30.581 | CE6: TRUE
A7: 43973 | B7: 14913.6 | C7: 0.0019280759 | D7: 0.055399095 | F7: 0.010849211 | G7: 0.0019280759 | H7: -0.0075144837 | I7: 0.055399095 | J7: 30.572 | K7: 45.214509 | L7: -14.642509 | M7: 0.055399095 | N7: TRUE | O7: TRUE | P7: -0.66873623 | Q7: -0.81118174 | R7: 9.7919763 | S7: 0.00074224967 | T7: -0.011965292 | U7: -0.010868397 | V7: 0.17520189 | W7: 0.00074224152 | X7: -0.011963391 | Y7: -0.010868278 | Z7: 0.17517405 | AA7: 0.0068292739 | AB7: -0.011966886 | AC7: -0.099997705 | AD7: 0.17522524 | AE7: 0.00074224461 | AF7: -0.011964713 | AG7: -0.010868323 | AH7: 0.17519342 | AI7: 0.00074225155 | AJ7: -0.011964591 | AK7: -0.010868425 | AL7: 0.17519163 | AM7: 0.0007422389 | AN7: -0.14429407 | AO7: -0.01086824 | AP7: 2.1128272 | AQ7: 0.016900039 | AR7: -0.011963966 | AS7: -0.24745897 | AT7: 0.17518247 | AU7: 0.017788016 | AV7: -0.22142565 | AW7: -0.26046118 | AX7: 3.2422271 | AY7: 0.0094282773 | AZ7: -0.2192633 | BA7: -0.13805363 | BB7: 3.2105648 | BC7: 0.00074226307 | BD7: -0.011964376 | BE7: -0.010868594 | BF7: 0.17518848 | BH7: 0.055399095 | BI7: -0.81118174 | BJ7: 0.00074224967 | BK7: -0.010868397 | BL7: 0.00074224152 | BM7: -0.010868278 | BN7: 0.0068292739 | BO7: -0.099997705 | BP7: 0.00074224461 | BQ7: -0.010868323 | BR7: 0.00074225155 | BS7: -0.010868425 | BT7: 0.0007422389 | BU7: -0.01086824 | BV7: 0.016900039 | BW7: -0.24745897 | BX7: 0.017788016 | BY7: -0.26046118 | BZ7: 0.0094282773 | CA7: -0.13805363 | CB7: 0.00074226307 | CC7: -0.010868594 | CD7: 30.572 | CE7: TRUE
A8: 43972 | B8: 14884.9 | C8: -0.0075144837 | D8: 0.097352839 | F8: 0.0019280759 | G8: -0.0075144837 | H8: 0.0075307923 | I8: 0.097352839 | J8: 30.763 | K8: 45.214509 | L8: -14.451509 | M8: 0.097352839 | N8: TRUE | O8: TRUE | P8: 0.055399095 | Q8: -1.4068954 | R8: -0.80060052 | S8: 0.0015144547 | T8: 0.00074224967 | U8: -0.021886156 | V8: -0.010726628 | W8: 0.0015145366 | X8: 0.00074224152 | Y8: -0.021887339 | Z8: -0.01072651 | AA8: 0.0015145415 | AB8: 0.0068292739 | AC8: -0.021887411 | AD8: -0.098693313 | AE8: 0.001514764 | AF8: 0.00074224461 | AG8: -0.021890625 | AH8: -0.010726555 | AI8: 0.0095738015 | AJ8: 0.00074225155 | AK8: -0.13835588 | AL8: -0.010726655 | AM8: 0.0015147114 | AN8: 0.0007422389 | AO8: -0.021889865 | AP8: -0.010726472 | AQ8: 0.0015146467 | AR8: 0.016900039 | AS8: -0.02188893 | AT8: -0.24423106 | AU8: 0.061317976 | AV8: 0.017788016 | AW8: -0.88613728 | AX8: -0.25706367 | AY8: 0.0015144979 | AZ8: 0.0094282773 | BA8: -0.02188678 | BB8: -0.13625283 | BC8: 0.015858909 | BD8: 0.00074226307 | BE8: -0.22918517 | BF8: -0.010726821 | BH8: 0.097352839 | BI8: -1.4068954 | BJ8: 0.0015144547 | BK8: -0.021886156 | BL8: 0.0015145366 | BM8: -0.021887339 | BN8: 0.0015145415 | BO8: -0.021887411 | BP8: 0.001514764 | BQ8: -0.021890625 | BR8: 0.0095738015 | BS8: -0.13835588 | BT8: 0.0015147114 | BU8: -0.021889865 | BV8: 0.0015146467 | BW8: -0.02188893 | BX8: 0.061317976 | BY8: -0.88613728 | BZ8: 0.0015144979 | CA8: -0.02188678 | CB8: 0.015858909 | CC8: -0.22918517 | CD8: 30.763 | CE8: TRUE
A9: 43971 | B9: 14997.6 | C9: 0.0075307923 | D9: 0.49790565 | F9: -0.0075144837 | G9: 0.0075307923 | H9: 0.016845501 | I9: 0.49790565 | J9: 31.376 | K9: 45.214509 | L9: -13.838509 | M9: 0.49790565 | N9: TRUE | O9: TRUE | P9: 0.097352839 | Q9: -6.8902719 | R9: -1.3472181 | S9: 0.0087608269 | T9: 0.0015144547 | U9: -0.12123678 | V9: -0.020957795 | W9: 0.0087604672 | X9: 0.0015145366 | Y9: -0.1212318 | Z9: -0.020958929 | AA9: 0.0087602504 | AB9: 0.0015145415 | AC9: -0.1212288 | AD9: -0.020958997 | AE9: 0.0087605666 | AF9: 0.001514764 | AG9: -0.12123318 | AH9: -0.020962075 | AI9: 0.13323097 | AJ9: 0.0095738015 | AK9: -1.8437179 | AL9: -0.13248714 | AM9: 0.0087612305 | AN9: 0.0015147114 | AO9: -0.12124237 | AP9: -0.020961347 | AQ9: 0.29459082 | AR9: 0.0015146467 | AS9: -4.0766977 | AT9: -0.020960451 | AU9: 0.0087610368 | AV9: 0.061317976 | AW9: -0.12123969 | AX9: -0.84854936 | AY9: 0.0087596785 | AZ9: 0.0015144979 | BA9: -0.12122089 | BB9: -0.020958393 | BC9: 0.0087598102 | BD9: 0.015858909 | BE9: -0.12122271 | BF9: -0.21946366 | BH9: 0.49790565 | BI9: -6.8902719 | BJ9: 0.0087608269 | BK9: -0.12123678 | BL9: 0.0087604672 | BM9: -0.1212318 | BN9: 0.0087602504 | BO9: -0.1212288 | BP9: 0.0087605666 | BQ9: -0.12123318 | BR9: 0.13323097 | BS9: -1.8437179 | BT9: 0.0087612305 | BU9: -0.12124237 | BV9: 0.29459082 | BW9: -4.0766977 | BX9: 0.0087610368 | BY9: -0.12123969 | BZ9: 0.0087596785 | CA9: -0.12122089 | CB9: 0.0087598102 | CC9: -0.12122271 | CD9: 31.376 | CE9: TRUE
A10: 43970 | B10: 14885.5 | C10: 0.016845501 | D10: 0.48645331 | F10: 0.0075307923 | G10: 0.016845501 | H10: 0.0089044015 | I10: 0.48645331 | J10: 31.684 | K10: 45.214509 | L10: -13.530509 | M10: 0.48645331 | N10: TRUE | O10: TRUE | P10: 0.49790565 | Q10: -6.5819609 | R10: -6.7369169 | S10: 0.0083449585 | T10: 0.0087608269 | U10: -0.11291154 | V10: -0.11853845 | W10: 0.0083455874 | X10: 0.0087604672 | Y10: -0.11292005 | Z10: -0.11853358 | AA10: 0.10563345 | AB10: 0.0087602504 | AC10: -1.4292744 | AD10: -0.11853065 | AE10: 0.0083454581 | AF10: 0.0087605666 | AG10: -0.1129183 | AH10: -0.11853493 | AI10: 0.008345337 | AJ10: 0.13323097 | AK10: -0.11291666 | AL10: -1.8026828 | AM10: 0.11475578 | AN10: 0.0087612305 | AO10: -1.5527042 | AP10: -0.11854391 | AQ10: 0.0083452898 | AR10: 0.29459082 | AS10: -0.11291602 | AT10: -3.9859638 | AU10: 0.20764727 | AV10: 0.0087610368 | AW10: -2.8095733 | AX10: -0.11854129 | AY10: 0.0083453181 | AZ10: 0.0087596785 | BA10: -0.1129164 | BB10: -0.11852291 | BC10: 0.0083448582 | BD10: 0.0087598102 | BE10: -0.11291018 | BF10: -0.11852469 | BH10: 0.48645331 | BI10: -6.5819609 | BJ10: 0.0083449585 | BK10: -0.11291154 | BL10: 0.0083455874 | BM10: -0.11292005 | BN10: 0.10563345 | BO10: -1.4292744 | BP10: 0.0083454581 | BQ10: -0.1129183 | BR10: 0.008345337 | BS10: -0.11291666 | BT10: 0.11475578 | BU10: -1.5527042 | BV10: 0.0083452898 | BW10: -0.11291602 | BX10: 0.20764727 | BY10: -2.8095733 | BZ10: 0.0083453181 | CA10: -0.1129164 | CB10: 0.0083448582 | CC10: -0.11291018 | CD10: 31.684 | CE10: TRUE
A11: 43966 | B11: 14638.9 | C11: 0.0089044015 | D11: -0.19248066 | F11: 0.016845501 | G11: 0.0089044015 | H11: 0.00044817695 | I11: -0.19248066 | J11: 32.881 | K11: 45.214509 | L11: -12.333509 | M11: -0.19248066 | N11: TRUE | O11: TRUE | P11: 0.48645331 | Q11: 2.3739619 | R11: -5.9996762 | S11: -0.015775974 | T11: 0.0083449585 | U11: 0.19457311 | V11: -0.10292262 | W11: -0.0074675971 | X11: 0.0083455874 | Y11: 0.092101674 | Z11: -0.10293038 | AA11: -0.0028211768 | AB11: 0.10563345 | AC11: 0.034795009 | AD11: -1.3028311 | AE11: -0.0028211577 | AF11: 0.0083454581 | AG11: 0.034794773 | AH11: -0.10292878 | AI11: -0.027990993 | AJ11: 0.008345337 | AK11: 0.34522715 | AL11: -0.10292729 | AM11: -0.015159416 | AN11: 0.11475578 | AO11: 0.18696879 | AP11: -1.4153415 | AQ11: -0.044681786 | AR11: 0.0083452898 | AS11: 0.5510832 | AT11: -0.1029267 | AU11: -0.044738488 | AV11: 0.20764727 | AW11: 0.55178253 | AX11: -2.5610194 | AY11: -0.028202953 | AZ11: 0.0083453181 | BA11: 0.34784137 | BB11: -0.10292705 | BC11: -0.002821116 | BD11: 0.0083448582 | BE11: 0.034794259 | BF11: -0.10292138 | BH11: -0.19248066 | BI11: 2.3739619 | BJ11: -0.015775974 | BK11: 0.19457311 | BL11: -0.0074675971 | BM11: 0.092101674 | BN11: -0.0028211768 | BO11: 0.034795009 | BP11: -0.0028211577 | BQ11: 0.034794773 | BR11: -0.027990993 | BS11: 0.34522715 | BT11: -0.015159416 | BU11: 0.18696879 | BV11: -0.044681786 | BW11: 0.5510832 | BX11: -0.044738488 | BY11: 0.55178253 | BZ11: -0.028202953 | CA11: 0.34784137 | CB11: -0.002821116 | CC11: 0.034794259 | CD11: 32.881 | CE11: TRUE
A12: 43965 | B12: 14509.7 | C12: 0.00044817695 | D12: 0.27620825 | F12: 0.0089044015 | G12: 0.00044817695 | H12: -0.025401177 | I12: 0.27620825 | J12: 33.035 | K12: 45.214509 | L12: -12.179509 | M12: 0.27620825 | N12: TRUE | O12: TRUE | P12: -0.19248066 | Q12: -3.3640807 | R12: 2.3443198 | S12: 0.0052182364 | T12: -0.015775974 | U12: -0.063555556 | V12: 0.19214361 | W12: 0.0052177766 | X12: -0.0074675971 | Y12: -0.063549956 | Z12: 0.090951664 | AA12: 0.081938723 | AB12: -0.0028211768 | AC12: -0.99797339 | AD12: 0.034360547 | AE12: 0.078871176 | AF12: -0.0028211577 | AG12: -0.96061218 | AH12: 0.034360315 | AI12: 0.0052180861 | AJ12: -0.027990993 | AK12: -0.063553726 | AL12: 0.34091654 | AM12: 0.0052184187 | AN12: -0.015159416 | AO12: -0.063557777 | AP12: 0.18463424 | AQ12: 0.078871721 | AR12: -0.044681786 | AS12: -0.96061882 | AT12: 0.5442022 | AU12: 0.0052180886 | AV12: -0.044738488 | AW12: -0.063553756 | AX12: 0.5448928 | AY12: 0.0052182125 | AZ12: -0.028202953 | BA12: -0.063555265 | BB12: 0.34349811 | BC12: 0.0052178061 | BD12: -0.002821116 | BE12: -0.063550315 | BF12: 0.034359806 | BH12: 0.27620825 | BI12: -3.3640807 | BJ12: 0.0052182364 | BK12: -0.063555556 | BL12: 0.0052177766 | BM12: -0.063549956 | BN12: 0.081938723 | BO12: -0.99797339 | BP12: 0.078871176 | BQ12: -0.96061218 | BR12: 0.0052180861 | BS12: -0.063553726 | BT12: 0.0052184187 | BU12: -0.063557777 | BV12: 0.078871721 | BW12: -0.96061882 | BX12: 0.0052180886 | BY12: -0.063553756 | BZ12: 0.0052182125 | CA12: -0.063555265 | CB12: 0.0052178061 | CC12: -0.063550315 | CD12: 33.035 | CE12: TRUE
A13: 43964 | B13: 14503.2 | C13: -0.025401177 | D13: 0.11645893 | F13: 0.00044817695 | G13: -0.025401177 | H13: -0.014698872 | I13: 0.11645893 | J13: 32.63 | K13: 45.214509 | L13: -12.584509 | M13: 0.11645893 | N13: TRUE | O13: TRUE | P13: 0.27620825 | Q13: -1.4655784 | R13: -3.4759451 | S13: 0.0021351589 | T13: 0.0052182364 | U13: -0.026869926 | V13: -0.065668941 | W13: 0.0021353922 | X13: 0.0052177766 | Y13: -0.026872862 | Z13: -0.065663155 | AA13: 0.002136241 | AB13: 0.081938723 | AC13: -0.026883544 | AD13: -1.0311586 | AE13: 0.0021353464 | AF13: 0.078871176 | AG13: -0.026872286 | AH13: -0.992555 | AI13: 0.0021353842 | AJ13: 0.0052180861 | AK13: -0.026872761 | AL13: -0.06566705 | AM13: 0.0021357551 | AN13: 0.0052184187 | AO13: -0.026877429 | AP13: -0.065671236 | AQ13: 0.048716392 | AR13: 0.078871721 | AS13: -0.61307186 | AT13: -0.99256186 | AU13: 0.050658549 | AV13: 0.0052180886 | AW13: -0.63751295 | AX13: -0.065667081 | AY13: 0.0021353989 | AZ13: 0.0052182125 | BA13: -0.026872946 | BB13: -0.06566864 | BC13: 0.0021353123 | BD13: 0.0052178061 | BE13: -0.026871856 | BF13: -0.065663526 | BH13: 0.11645893 | BI13: -1.4655784 | BJ13: 0.0021351589 | BK13: -0.026869926 | BL13: 0.0021353922 | BM13: -0.026872862 | BN13: 0.002136241 | BO13: -0.026883544 | BP13: 0.0021353464 | BQ13: -0.026872286 | BR13: 0.0021353842 | BS13: -0.026872761 | BT13: 0.0021357551 | BU13: -0.026877429 | BV13: 0.048716392 | BW13: -0.61307186 | BX13: 0.050658549 | BY13: -0.63751295 | BZ13: 0.0021353989 | CA13: -0.026872946 | CB13: 0.0021353123 | CC13: -0.026871856 | CD13: 32.63 | CE13: TRUE
... A48: 43914 | B48: 12571.1 | C48: 0.1195707 | D48: -0.1196669 | F48: 0.045191002 | G48: 0.1195707 | H48: -0.052591152 | I48: -0.1196669 | J48: 66.918001 | K48: 45.214509 | L48: 21.703492 | M48: -0.1196669 | N48: TRUE | O48: TRUE | P48: 0.069990374 | Q48: -2.5971895 | R48: 1.5190355 | S48: -0.0069170545 | T48: 0.0012419563 | U48: -0.15012423 | V48: 0.026954787 | W48: -0.0015335211 | X48: 0.0012419151 | Y48: -0.033282764 | Z48: 0.026953894 | AA48: -0.011790363 | AB48: 0.0012419913 | AC48: -0.25589205 | AD48: 0.026955548 | AE48: -0.0089073539 | AF48: 0.0085324104 | AG48: -0.19332068 | AH48: 0.1851831 | AI48: -0.0015335814 | AJ48: 0.0045154787 | AK48: -0.03328407 | AL48: 0.098001656 | AM48: -0.009717408 | AN48: 0.010839097 | AO48: -0.21090168 | AP48: 0.23524626 | AQ48: -0.0015335828 | AR48: 0.0037028937 | AS48: -0.033284102 | AT48: 0.080365722 | AU48: -0.064409877 | AV48: 0.023359487 | AW48: -1.3979192 | AX48: 0.50698242 | AY48: -0.0015335674 | AZ48: 0.0082409009 | BA48: -0.033283769 | BB48: 0.17885632 | BC48: -0.011790588 | BD48: 0.0070742442 | BE48: -0.25589692 | BF48: 0.1535358 | BH48: -0.1196669 | BI48: -2.5971895 | BJ48: -0.0069170545 | BK48: -0.15012423 | BL48: -0.0015335211 | BM48: -0.033282764 | BN48: -0.011790363 | BO48: -0.25589205 | BP48: -0.0089073539 | BQ48: -0.19332068 | BR48: -0.0015335814 | BS48: -0.03328407 | BT48: -0.009717408 | BU48: -0.21090168 | BV48: -0.0015335828 | BW48: -0.033284102 | BX48: -0.064409877 | BY48: -1.3979192 | BZ48: -0.0015335674 | CA48: -0.033283769 | CB48: -0.011790588 | CC48: -0.25589692 | CD48: 66.918001 | CE48: TRUE
A49: 43913 | C49: -0.052591152
R59: 0 | V59: 0
R60: 0 | V60: 0
R61: 0 | V61: 0
R62: 0 | V62: 0
R63: 0 | V63: 0
R64: 0 | V64: 0
R65: 0 | V65: 0
R66: 0 | V66: 0
R67: 0 | V67: 0
R68: 0 | V68: 0
R69: 0 | V69: 0
R70: 0 | V70: 0
... R565: 0 | V565: 0

Sheet Adj close price
A1: ='ALL VARS'!A1 -> Date | B1: ='ALL VARS'!B1 -> Adj close price
A2: ='ALL VARS'!A2 -> 43980 | B2: ='ALL VARS'!B2 -> 15192.8
A3: ='ALL VARS'!A3 -> 43979 | B3: ='ALL VARS'!B3 -> 15262.7
A4: ='ALL VARS'!A4 -> 43978 | B4: ='ALL VARS'!B4 -> 15272
A5: ='ALL VARS'!A5 -> 43977 | B5: ='ALL VARS'!B5 -> 15148.1
A6: ='ALL VARS'!A6 -> 43976 | B6: ='ALL VARS'!B6 -> 15075.4
A7: ='ALL VARS'!A7 -> 43973 | B7: ='ALL VARS'!B7 -> 14913.6
A8: ='ALL VARS'!A8 -> 43972 | B8: ='ALL VARS'!B8 -> 14884.9
A9: ='ALL VARS'!A9 -> 43971 | B9: ='ALL VARS'!B9 -> 14997.6
A10: ='ALL VARS'!A10 -> 43970 | B10: ='ALL VARS'!B10 -> 14885.5
A11: ='ALL VARS'!A11 -> 43966 | B11: ='ALL VARS'!B11 -> 14638.9
A12: ='ALL VARS'!A12 -> 43965 | B12: ='ALL VARS'!B12 -> 14509.7
... A19: ='ALL VARS'!A19 -> 43956 | B19: ='ALL VARS'!B19 -> 14811.6
A20: ='ALL VARS'!A20 -> 43955 | B20: ='ALL VARS'!B20 -> 14745 | D20: Max | E20: =MAX(B2:B48) -> 15272
A21: ='ALL VARS'!A21 -> 43952 | B21: ='ALL VARS'!B21 -> 14620.3 | D21: Q3 | E21: =QUARTILE(B2:B48, 3) -> 14883.05
A22: ='ALL VARS'!A22 -> 43951 | B22: ='ALL VARS'!B22 -> 14780.7 | D22: Median | E22: =MEDIAN(B2:B48) -> 14503.2
A23: ='ALL VARS'!A23 -> 43950 | B23: ='ALL VARS'!B23 -> 15228.1 | D23: Q1 | E23: =QUARTILE(B2:B48, 1) -> 13912.5
A24: ='ALL VARS'!A24 -> 43949 | B24: ='ALL VARS'!B24 -> 14798.3 | D24: Min | E24: =MIN(B2:B48) -> 12571.1
A25: ='ALL VARS'!A25 -> 43948 | B25: ='ALL VARS'!B25 -> 14642.1
A26: ='ALL VARS'!A26 -> 43945 | B26: ='ALL VARS'!B26 -> 14420.4
A27: ='ALL VARS'!A27 -> 43944 | B27: ='ALL VARS'!B27 -> 14251.1
A28: ='ALL VARS'!A28 -> 43943 | B28: ='ALL VARS'!B28 -> 14288.2
A29: ='ALL VARS'!A29 -> 43942 | B29: ='ALL VARS'!B29 -> 13940.1
A30: ='ALL VARS'!A30 -> 43941 | B30: ='ALL VARS'!B30 -> 14388.3
A31: ='ALL VARS'!A31 -> 43938 | B31: ='ALL VARS'!B31 -> 14359.9
A32: ='ALL VARS'!A32 -> 43937 | B32: ='ALL VARS'!B32 -> 13899.3
A33: ='ALL VARS'!A33 -> 43936 | B33: ='ALL VARS'!B33 -> 13958.6
A34: ='ALL VARS'!A34 -> 43935 | B34: ='ALL VARS'!B34 -> 14258.4
A35: ='ALL VARS'!A35 -> 43934 | B35: ='ALL VARS'!B35 -> 14075.9
A36: ='ALL VARS'!A36 -> 43930 | B36: ='ALL VARS'!B36 -> 14166.6
... A48: ='ALL VARS'!A48 -> 43914 | B48: ='ALL VARS'!B48 -> 12571.1
B51: =(B2-'[1]Adj close price'!$B$2)/'[1]Adj close price'!$B$2 -> 0.35305694

Sheet Eq4 avec Sent_t__+__1
A1: ='ALL VARS'!A1 -> Date | B1: ='ALL VARS'!F1 -> Daily Return-Adj_t_+1 | C1: ='ALL VARS'!G1 -> Daily Return-Adj_t | D1: ='ALL VARS'!H1 -> Daily Return-Adj_t_minus_1 | E1: ='ALL VARS'!P1 -> Sent_t_+_1 | F1: ='ALL VARS'!R1 -> Sent_t_+_1 * (VIX_10_t minus VIX_bar_10) | G1: ='ALL VARS'!J1 -> VIX_10_t
A2: ='ALL VARS'!A2 -> 43980 | B2: ='ALL VARS'!F2 -> 0.02309392 | C2: ='ALL VARS'!G2 -> -0.0045798181 | D2: ='ALL VARS'!H2 -> -0.0006089448 | E2: ='ALL VARS'!P2 -> -0.067721572 | F2: ='ALL VARS'!R2 -> -0.85012213 | G2: ='ALL VARS'!J2 -> 29.423 | I2: RAPPORT DÉTAILLÉ
A3: ='ALL VARS'!A3 -> 43979 | B3: ='ALL VARS'!F3 -> -0.0045798181 | C3: ='ALL VARS'!G3 -> -0.0006089448 | D3: ='ALL VARS'!H3 -> 0.0081792696 | E3: ='ALL VARS'!P3 -> -0.24457772 | F3: ='ALL VARS'!R3 -> 3.6986288 | G3: ='ALL VARS'!J3 -> 30.092
A4: ='ALL VARS'!A4 -> 43978 | B4: ='ALL VARS'!F4 -> -0.0006089448 | C4: ='ALL VARS'!G4 -> 0.0081792696 | D4: ='ALL VARS'!H4 -> 0.0048223739 | E4: ='ALL VARS'!P4 -> 0.0062640198 | F4: ='ALL VARS'!R4 -> -0.091332596 | G4: ='ALL VARS'!J4 -> 30.634 | I4: Statistiques de la régression
A5: ='ALL VARS'!A5 -> 43977 | B5: ='ALL VARS'!F5 -> 0.0081792696 | C5: ='ALL VARS'!G5 -> 0.0048223739 | D5: ='ALL VARS'!H5 -> 0.010849211 | E5: ='ALL VARS'!P5 -> -0.23609327 | F5: ='ALL VARS'!R5 -> 3.4527481 | G5: ='ALL VARS'!J5 -> 30.59 | I5: Coefficient de détermination multiple | J5: 0.40807591
A6: ='ALL VARS'!A6 -> 43976 | B6: ='ALL VARS'!F6 -> 0.0048223739 | C6: ='ALL VARS'!G6 -> 0.010849211 | D6: ='ALL VARS'!H6 -> 0.0019280759 | E6: ='ALL VARS'!P6 -> 0.13119693 | F6: ='ALL VARS'!R6 -> -1.9198715 | G6: ='ALL VARS'!J6 -> 30.581 | I6: Coefficient de détermination R^2 | J6: 0.16652595
A7: ='ALL VARS'!A7 -> 43973 | B7: ='ALL VARS'!F7 -> 0.010849211 | C7: ='ALL VARS'!G7 -> 0.0019280759 | D7: ='ALL VARS'!H7 -> -0.0075144837 | E7: ='ALL VARS'!P7 -> -0.66873623 | F7: ='ALL VARS'!R7 -> 9.7919763 | G7: ='ALL VARS'!J7 -> 30.572 | I7: Coefficient de détermination R^2 | J7: 0.063337941
A8: ='ALL VARS'!A8 -> 43972 | B8: ='ALL VARS'!F8 -> 0.0019280759 | C8: ='ALL VARS'!G8 -> -0.0075144837 | D8: ='ALL VARS'!H8 -> 0.0075307923 | E8: ='ALL VARS'!P8 -> 0.055399095 | F8: ='ALL VARS'!R8 -> -0.80060052 | G8: ='ALL VARS'!J8 -> 30.763 | I8: Erreur-type | J8: 0.01977249
A9: ='ALL VARS'!A9 -> 43971 | B9: ='ALL VARS'!F9 -> -0.0075144837 | C9: ='ALL VARS'!G9 -> 0.0075307923 | D9: ='ALL VARS'!H9 -> 0.016845501 | E9: ='ALL VARS'!P9 -> 0.097352839 | F9: ='ALL VARS'!R9 -> -1.3472181 | G9: ='ALL VARS'!J9 -> 31.376 | I9: Observations | J9: 47
A10: ='ALL VARS'!A10 -> 43970 | B10: ='ALL VARS'!F10 -> 0.0075307923 | C10: ='ALL VARS'!G10 -> 0.016845501 | D10: ='ALL VARS'!H10 -> 0.0089044015 | E10: ='ALL VARS'!P10 -> 0.49790565 | F10: ='ALL VARS'!R10 -> -6.7369169 | G10: ='ALL VARS'!J10 -> 31.684
A11: ='ALL VARS'!A11 -> 43966 | B11: ='ALL VARS'!F11 -> 0.016845501 | C11: ='ALL VARS'!G11 -> 0.0089044015 | D11: ='ALL VARS'!H11 -> 0.00044817695 | E11: ='ALL VARS'!P11 -> 0.48645331 | F11: ='ALL VARS'!R11 -> -5.9996762 | G11: ='ALL VARS'!J11 -> 32.881 | I11: ANALYSE DE VARIANCE
A12: ='ALL VARS'!A12 -> 43965 | B12: ='ALL VARS'!F12 -> 0.0089044015 | C12: ='ALL VARS'!G12 -> 0.00044817695 | D12: ='ALL VARS'!H12 -> -0.025401177 | E12: ='ALL VARS'!P12 -> -0.19248066 | F12: ='ALL VARS'!R12 -> 2.3443198 | G12: ='ALL VARS'!J12 -> 33.035 | J12: Degré de liberté | K12: Somme des carrés | L12: Moyenne des carrés | M12: F | N12: Valeur critique de F
A13: ='ALL VARS'!A13 -> 43964 | B13: ='ALL VARS'!F13 -> 0.00044817695 | C13: ='ALL VARS'!G13 -> -0.025401177 | D13: ='ALL VARS'!H13 -> -0.014698872 | E13: ='ALL VARS'!P13 -> 0.27620825 | F13: ='ALL VARS'!R13 -> -3.4759451 | G13: ='ALL VARS'!J13 -> 32.63 | I13: Régression | J13: 5 | K13: 0.0032806646 | L13: 0.00065613292 | M13: 1.6782981 | N13: 0.16151592
A14: ='ALL VARS'!A14 -> 43963 | B14: ='ALL VARS'!F14 -> -0.025401177 | C14: ='ALL VARS'!G14 -> -0.014698872 | D14: ='ALL VARS'!H14 -> 0.0091270288 | E14: ='ALL VARS'!P14 -> 0.11645893 | F14: ='ALL VARS'!R14 -> -1.4594061 | G14: ='ALL VARS'!J14 -> 32.683 | I14: Résidus | J14: 42 | K14: 0.016419957 | L14: 0.00039095135
A15: ='ALL VARS'!A15 -> 43962 | B15: ='ALL VARS'!F15 -> -0.014698872 | C15: ='ALL VARS'!G15 -> 0.0091270288 | D15: ='ALL VARS'!H15 -> 0.0089592895 | E15: ='ALL VARS'!P15 -> -0.15498586 | F15: ='ALL VARS'!R15 -> 1.8535547 | G15: ='ALL VARS'!J15 -> 33.255 | I15: Total | J15: 47 | K15: 0.019700621
A16: ='ALL VARS'!A16 -> 43959 | B16: ='ALL VARS'!F16 -> 0.0091270288 | C16: ='ALL VARS'!G16 -> 0.0089592895 | D16: ='ALL VARS'!H16 -> 0.0002022831 | E16: ='ALL VARS'!P16 -> 0.095311683 | F16: ='ALL VARS'!R16 -> -1.0641081 | G16: ='ALL VARS'!J16 -> 34.05
A17: ='ALL VARS'!A17 -> 43958 | B17: ='ALL VARS'!F17 -> 0.0089592895 | C17: ='ALL VARS'!G17 -> 0.0002022831 | D17: ='ALL VARS'!H17 -> 0.0012895694 | E17: ='ALL VARS'!P17 -> 0.2917263 | F17: ='ALL VARS'!R17 -> -2.9670048 | G17: ='ALL VARS'!J17 -> 35.044 | J17: Coefficients | K17: Erreur-type | L17: Statistique t | M17: Probabilité | N17: Limite inférieure pour seuil de confiance = 95% | O17: Limite supérieure pour seuil de confiance = 95% | P17: Limite inférieure pour seuil de confiance = 95,0% | Q17: Limite supérieure pour seuil de confiance = 95,0%
A18: ='ALL VARS'!A18 -> 43957 | B18: ='ALL VARS'!F18 -> 0.0002022831 | C18: ='ALL VARS'!G18 -> 0.0012895694 | D18: ='ALL VARS'!H18 -> 0.0045167588 | E18: ='ALL VARS'!P18 -> -0.23442382 | F18: ='ALL VARS'!R18 -> 2.1999524 | G18: ='ALL VARS'!J18 -> 35.83 | I18: Constante | J18: 0 | K18: #N/A | L18: #N/A | M18: #N/A | N18: #N/A | O18: #N/A | P18: #N/A | Q18: #N/A
A19: ='ALL VARS'!A19 -> 43956 | B19: ='ALL VARS'!F19 -> 0.0012895694 | C19: ='ALL VARS'!G19 -> 0.0045167588 | D19: ='ALL VARS'!H19 -> 0.0085292502 | E19: ='ALL VARS'!P19 -> -0.021146204 | F19: ='ALL VARS'!R19 -> 0.17349422 | G19: ='ALL VARS'!J19 -> 37.01 | I19: Daily Return-Adj_t | J19: 0.016269057 | K19: 0.11491613 | L19: 0.14157331 | M19: 0.88809396 | N19: -0.21564108 | O19: 0.2481792 | P19: -0.21564108 | Q19: 0.2481792
A20: ='ALL VARS'!A20 -> 43955 | B20: ='ALL VARS'!F20 -> 0.0045167588 | C20: ='ALL VARS'!G20 -> 0.0085292502 | D20: ='ALL VARS'!H20 -> -0.010852016 | E20: ='ALL VARS'!P20 -> 0.23377029 | F20: ='ALL VARS'!R20 -> -1.7342269 | G20: ='ALL VARS'!J20 -> 37.796 | I20: Daily Return-Adj_t_minus_1 | J20: -0.085848573 | K20: 0.11607052 | L20: -0.73962426 | M20: 0.46364221 | N20: -0.32008837 | O20: 0.14839122 | P20: -0.32008837 | Q20: 0.14839122
A21: ='ALL VARS'!A21 -> 43952 | B21: ='ALL VARS'!F21 -> 0.0085292502 | C21: ='ALL VARS'!G21 -> -0.010852016 | D21: ='ALL VARS'!H21 -> -0.029379859 | E21: ='ALL VARS'!P21 -> -0.15081174 | F21: ='ALL VARS'!R21 -> 1.1043202 | G21: ='ALL VARS'!J21 -> 37.892001 | I21: Sent_t_+_1 | J21: 0.018643986 | K21: 0.011522498 | L21: 1.6180506 | M21: 0.11313831 | N21: -0.0046093574 | O21: 0.041897329 | P21: -0.0046093574 | Q21: 0.041897329
A22: ='ALL VARS'!A22 -> 43951 | B22: ='ALL VARS'!F22 -> -0.010852016 | C22: ='ALL VARS'!G22 -> -0.029379859 | D22: ='ALL VARS'!H22 -> 0.029043864 | E22: ='ALL VARS'!P22 -> -0.15819044 | F22: ='ALL VARS'!R22 -> 1.0640693 | G22: ='ALL VARS'!J22 -> 38.488001 | I22: Sent_t_+_1 * (VIX_10_t minus VIX_bar_10) | J22: 0.0012509781 | K22: 0.00085071203 | L22: 1.4705071 | M22: 0.14887705 | N22: -0.00046582832 | O22: 0.0029677844 | P22: -0.00046582832 | Q22: 0.0029677844
A23: ='ALL VARS'!A23 -> 43950 | B23: ='ALL VARS'!F23 -> -0.029379859 | C23: ='ALL VARS'!G23 -> 0.029043864 | D23: ='ALL VARS'!H23 -> 0.010667882 | E23: ='ALL VARS'!P23 -> -0.11695044 | F23: ='ALL VARS'!R23 -> 0.67427873 | G23: ='ALL VARS'!J23 -> 39.449001 | I23: VIX_10_t | J23: 0.00019072378 | K23: 7.4975228e-05 | L23: 2.5438239 | M23: 0.014733096 | N23: 3.9417641e-05 | O23: 0.00034202992 | P23: 3.9417641e-05 | Q23: 0.00034202992
A24: ='ALL VARS'!A24 -> 43949 | B24: ='ALL VARS'!F24 -> 0.029043864 | C24: ='ALL VARS'!G24 -> 0.010667882 | D24: ='ALL VARS'!H24 -> 0.015373999 | E24: ='ALL VARS'!P24 -> 0.0066089131 | F24: ='ALL VARS'!R24 -> -0.03533461 | G24: ='ALL VARS'!J24 -> 39.868001
A25: ='ALL VARS'!A25 -> 43948 | B25: ='ALL VARS'!F25 -> 0.010667882 | C25: ='ALL VARS'!G25 -> 0.015373999 | D25: ='ALL VARS'!H25 -> 0.01187984 | E25: ='ALL VARS'!P25 -> -0.16266929 | F25: ='ALL VARS'!R25 -> 0.74152941 | G25: ='ALL VARS'!J25 -> 40.656
A26: ='ALL VARS'!A26 -> 43945 | B26: ='ALL VARS'!F26 -> 0.015373999 | C26: ='ALL VARS'!G26 -> 0.01187984 | D26: ='ALL VARS'!H26 -> -0.0025965892 | E26: ='ALL VARS'!P26 -> -0.43920172 | F26: ='ALL VARS'!R26 -> 1.7500032 | G26: ='ALL VARS'!J26 -> 41.23
A27: ='ALL VARS'!A27 -> 43944 | B27: ='ALL VARS'!F27 -> 0.01187984 | C27: ='ALL VARS'!G27 -> -0.0025965892 | D27: ='ALL VARS'!H27 -> 0.024971169 | E27: ='ALL VARS'!P27 -> -0.020552383 | F27: ='ALL VARS'!R27 -> 0.077842341 | G27: ='ALL VARS'!J27 -> 41.427
A28: ='ALL VARS'!A28 -> 43943 | B28: ='ALL VARS'!F28 -> -0.0025965892 | C28: ='ALL VARS'!G28 -> 0.024971169 | D28: ='ALL VARS'!H28 -> -0.031150324 | E28: ='ALL VARS'!P28 -> -0.4435997 | F28: ='ALL VARS'!R28 -> 1.4707589 | G28: ='ALL VARS'!J28 -> 41.899
A29: ='ALL VARS'!A29 -> 43942 | B29: ='ALL VARS'!F29 -> 0.024971169 | C29: ='ALL VARS'!G29 -> -0.031150324 | D29: ='ALL VARS'!H29 -> 0.0019776888 | E29: ='ALL VARS'!P29 -> 0.070537304 | F29: ='ALL VARS'!R29 -> -0.2350662 | G29: ='ALL VARS'!J29 -> 41.882
A30: ='ALL VARS'!A30 -> 43941 | B30: ='ALL VARS'!F30 -> -0.031150324 | C30: ='ALL VARS'!G30 -> 0.0019776888 | D30: ='ALL VARS'!H30 -> 0.033138402 | E30: ='ALL VARS'!P30 -> 0.061557357 | F30: ='ALL VARS'!R30 -> -0.18685793 | G30: ='ALL VARS'!J30 -> 42.179
A31: ='ALL VARS'!A31 -> 43938 | B31: ='ALL VARS'!F31 -> 0.0019776888 | C31: ='ALL VARS'!G31 -> 0.033138402 | D31: ='ALL VARS'!H31 -> -0.0042482631 | E31: ='ALL VARS'!P31 -> 0.33201584 | F31: ='ALL VARS'!R31 -> -0.58418502 | G31: ='ALL VARS'!J31 -> 43.454999
A32: ='ALL VARS'!A32 -> 43937 | B32: ='ALL VARS'!F32 -> 0.033138402 | C32: ='ALL VARS'!G32 -> -0.0042482631 | D32: ='ALL VARS'!H32 -> -0.021026256 | E32: ='ALL VARS'!P32 -> -0.010891217 | F32: ='ALL VARS'!R32 -> 0.0007025871 | G32: ='ALL VARS'!J32 -> 45.149999
A33: ='ALL VARS'!A33 -> 43936 | B33: ='ALL VARS'!F33 -> -0.0042482631 | C33: ='ALL VARS'!G33 -> -0.021026256 | D33: ='ALL VARS'!H33 -> 0.012965423 | E33: ='ALL VARS'!P33 -> -0.018410735 | F33: ='ALL VARS'!R33 -> -0.022193968 | G33: ='ALL VARS'!J33 -> 46.42
A34: ='ALL VARS'!A34 -> 43935 | B34: ='ALL VARS'!F34 -> -0.021026256 | C34: ='ALL VARS'!G34 -> 0.012965423 | D34: ='ALL VARS'!H34 -> -0.006402328 | E34: ='ALL VARS'!P34 -> -0.32017185 | F34: ='ALL VARS'!R34 -> -1.0045363 | G34: ='ALL VARS'!J34 -> 48.352
A35: ='ALL VARS'!A35 -> 43934 | B35: ='ALL VARS'!F35 -> 0.012965423 | C35: ='ALL VARS'!G35 -> -0.006402328 | D35: ='ALL VARS'!H35 -> 0.017298909 | E35: ='ALL VARS'!P35 -> 0.10925813 | F35: ='ALL VARS'!R35 -> 0.60905847 | G35: ='ALL VARS'!J35 -> 50.789
... A48: ='ALL VARS'!A48 -> 43914 | B48: ='ALL VARS'!F48 -> 0.045191002 | C48: ='ALL VARS'!G48 -> 0.1195707 | D48: ='ALL VARS'!H48 -> -0.052591152 | E48: ='ALL VARS'!P48 -> 0.069990374 | F48: ='ALL VARS'!R48 -> 1.5190355 | G48: ='ALL VARS'!J48 -> 66.918001

Sheet Eq4 avec Sent__t_+_1_k, k=0
A1: ='ALL VARS'!A1 -> Date | B1: ='ALL VARS'!F1 -> Daily Return-Adj_t_+1 | C1: ='ALL VARS'!G1 -> Daily Return-Adj_t | D1: ='ALL VARS'!H1 -> Daily Return-Adj_t_minus_1 | E1: ='ALL VARS'!T1 -> Sent_t_+_1_k, k=0 | F1: ='ALL VARS'!V1 -> Sent_t_+_1_k, k=0 * (VIX_10_t minus VIX_bar_10) | G1: ='ALL VARS'!J1 -> VIX_10_t
A2: ='ALL VARS'!A2 -> 43980 | B2: ='ALL VARS'!F2 -> 0.02309392 | C2: ='ALL VARS'!G2 -> -0.0045798181 | D2: ='ALL VARS'!H2 -> -0.0006089448 | E2: ='ALL VARS'!T2 -> -0.0016831778 | F2: ='ALL VARS'!V2 -> 0.026579917 | G2: ='ALL VARS'!J2 -> 29.423 | I2: RAPPORT DÉTAILLÉ
A3: ='ALL VARS'!A3 -> 43979 | B3: ='ALL VARS'!F3 -> -0.0045798181 | C3: ='ALL VARS'!G3 -> -0.0006089448 | D3: ='ALL VARS'!H3 -> 0.0081792696 | E3: ='ALL VARS'!T3 -> -0.040665115 | F3: ='ALL VARS'!V3 -> 0.61495856 | G3: ='ALL VARS'!J3 -> 30.092
A4: ='ALL VARS'!A4 -> 43978 | B4: ='ALL VARS'!F4 -> -0.0006089448 | C4: ='ALL VARS'!G4 -> 0.0081792696 | D4: ='ALL VARS'!H4 -> 0.0048223739 | E4: ='ALL VARS'!T4 -> 0.00013925055 | F4: ='ALL VARS'!V4 -> -0.0020303439 | G4: ='ALL VARS'!J4 -> 30.634 | I4: Statistiques de la régression
A5: ='ALL VARS'!A5 -> 43977 | B5: ='ALL VARS'!F5 -> 0.0081792696 | C5: ='ALL VARS'!G5 -> 0.0048223739 | D5: ='ALL VARS'!H5 -> 0.010849211 | E5: ='ALL VARS'!T5 -> -0.0035602667 | F5: ='ALL VARS'!V5 -> 0.052067151 | G5: ='ALL VARS'!J5 -> 30.59 | I5: Coefficient de détermination multiple | J5: 0.36353548
A6: ='ALL VARS'!A6 -> 43976 | B6: ='ALL VARS'!F6 -> 0.0048223739 | C6: ='ALL VARS'!G6 -> 0.010849211 | D6: ='ALL VARS'!H6 -> 0.0019280759 | E6: ='ALL VARS'!T6 -> 0.0022716123 | F6: ='ALL VARS'!V6 -> -0.033241659 | G6: ='ALL VARS'!J6 -> 30.581 | I6: Coefficient de détermination R^2 | J6: 0.13215805
A7: ='ALL VARS'!A7 -> 43973 | B7: ='ALL VARS'!F7 -> 0.010849211 | C7: ='ALL VARS'!G7 -> 0.0019280759 | D7: ='ALL VARS'!H7 -> -0.0075144837 | E7: ='ALL VARS'!T7 -> -0.011965292 | F7: ='ALL VARS'!V7 -> 0.17520189 | G7: ='ALL VARS'!J7 -> 30.572 | I7: Coefficient de détermination R^2 | J7: 0.025696909
A8: ='ALL VARS'!A8 -> 43972 | B8: ='ALL VARS'!F8 -> 0.0019280759 | C8: ='ALL VARS'!G8 -> -0.0075144837 | D8: ='ALL VARS'!H8 -> 0.0075307923 | E8: ='ALL VARS'!T8 -> 0.00074224967 | F8: ='ALL VARS'!V8 -> -0.010726628 | G8: ='ALL VARS'!J8 -> 30.763 | I8: Erreur-type | J8: 0.020176026
A9: ='ALL VARS'!A9 -> 43971 | B9: ='ALL VARS'!F9 -> -0.0075144837 | C9: ='ALL VARS'!G9 -> 0.0075307923 | D9: ='ALL VARS'!H9 -> 0.016845501 | E9: ='ALL VARS'!T9 -> 0.0015144547 | F9: ='ALL VARS'!V9 -> -0.020957795 | G9: ='ALL VARS'!J9 -> 31.376 | I9: Observations | J9: 47
A10: ='ALL VARS'!A10 -> 43970 | B10: ='ALL VARS'!F10 -> 0.0075307923 | C10: ='ALL VARS'!G10 -> 0.016845501 | D10: ='ALL VARS'!H10 -> 0.0089044015 | E10: ='ALL VARS'!T10 -> 0.0087608269 | F10: ='ALL VARS'!V10 -> -0.11853845 | G10: ='ALL VARS'!J10 -> 31.684
A11: ='ALL VARS'!A11 -> 43966 | B11: ='ALL VARS'!F11 -> 0.016845501 | C11: ='ALL VARS'!G11 -> 0.0089044015 | D11: ='ALL VARS'!H11 -> 0.00044817695 | E11: ='ALL VARS'!T11 -> 0.0083449585 | F11: ='ALL VARS'!V11 -> -0.10292262 | G11: ='ALL VARS'!J11 -> 32.881 | I11: ANALYSE DE VARIANCE
A12: ='ALL VARS'!A12 -> 43965 | B12: ='ALL VARS'!F12 -> 0.0089044015 | C12: ='ALL VARS'!G12 -> 0.00044817695 | D12: ='ALL VARS'!H12 -> -0.025401177 | E12: ='ALL VARS'!T12 -> -0.015775974 | F12: ='ALL VARS'!V12 -> 0.19214361 | G12: ='ALL VARS'!J12 -> 33.035 | J12: Degré de liberté | K12: Somme des carrés | L12: Moyenne des carrés | M12: F | N12: Valeur critique de F
A13: ='ALL VARS'!A13 -> 43964 | B13: ='ALL VARS'!F13 -> 0.00044817695 | C13: ='ALL VARS'!G13 -> -0.025401177 | D13: ='ALL VARS'!H13 -> -0.014698872 | E13: ='ALL VARS'!T13 -> 0.0052182364 | F13: ='ALL VARS'!V13 -> -0.065668941 | G13: ='ALL VARS'!J13 -> 32.63 | I13: Régression | J13: 5 | K13: 0.0026035956 | L13: 0.00052071913 | M13: 1.2791818 | N13: 0.29139467
A14: ='ALL VARS'!A14 -> 43963 | B14: ='ALL VARS'!F14 -> -0.025401177 | C14: ='ALL VARS'!G14 -> -0.014698872 | D14: ='ALL VARS'!H14 -> 0.0091270288 | E14: ='ALL VARS'!T14 -> 0.0021351589 | F14: ='ALL VARS'!V14 -> -0.026756762 | G14: ='ALL VARS'!J14 -> 32.683 | I14: Résidus | J14: 42 | K14: 0.017097026 | L14: 0.00040707204
A15: ='ALL VARS'!A15 -> 43962 | B15: ='ALL VARS'!F15 -> -0.014698872 | C15: ='ALL VARS'!G15 -> 0.0091270288 | D15: ='ALL VARS'!H15 -> 0.0089592895 | E15: ='ALL VARS'!T15 -> -0.0026453927 | F15: ='ALL VARS'!V15 -> 0.031637596 | G15: ='ALL VARS'!J15 -> 33.255 | I15: Total | J15: 47 | K15: 0.019700621
A16: ='ALL VARS'!A16 -> 43959 | B16: ='ALL VARS'!F16 -> 0.0091270288 | C16: ='ALL VARS'!G16 -> 0.0089592895 | D16: ='ALL VARS'!H16 -> 0.0002022831 | E16: ='ALL VARS'!T16 -> 0.0015914759 | F16: ='ALL VARS'!V16 -> -0.017768047 | G16: ='ALL VARS'!J16 -> 34.05
A17: ='ALL VARS'!A17 -> 43958 | B17: ='ALL VARS'!F17 -> 0.0089592895 | C17: ='ALL VARS'!G17 -> 0.0002022831 | D17: ='ALL VARS'!H17 -> 0.0012895694 | E17: ='ALL VARS'!T17 -> 0.040751833 | F17: ='ALL VARS'!V17 -> -0.41446687 | G17: ='ALL VARS'!J17 -> 35.044 | J17: Coefficients | K17: Erreur-type | L17: Statistique t | M17: Probabilité | N17: Limite inférieure pour seuil de confiance = 95% | O17: Limite supérieure pour seuil de confiance = 95% | P17: Limite inférieure pour seuil de confiance = 95,0% | Q17: Limite supérieure pour seuil de confiance = 95,0%
A18: ='ALL VARS'!A18 -> 43957 | B18: ='ALL VARS'!F18 -> 0.0002022831 | C18: ='ALL VARS'!G18 -> 0.0012895694 | D18: ='ALL VARS'!H18 -> 0.0045167588 | E18: ='ALL VARS'!T18 -> -0.0035818738 | F18: ='ALL VARS'!V18 -> 0.033614125 | G18: ='ALL VARS'!J18 -> 35.83 | I18: Constante | J18: 0 | K18: #N/A | L18: #N/A | M18: #N/A | N18: #N/A | O18: #N/A | P18: #N/A | Q18: #N/A
A19: ='ALL VARS'!A19 -> 43956 | B19: ='ALL VARS'!F19 -> 0.0012895694 | C19: ='ALL VARS'!G19 -> 0.0045167588 | D19: ='ALL VARS'!H19 -> 0.0085292502 | E19: ='ALL VARS'!T19 -> -0.00038910877 | F19: ='ALL VARS'!V19 -> 0.0031924463 | G19: ='ALL VARS'!J19 -> 37.01 | I19: Daily Return-Adj_t | J19: -0.0042937638 | K19: 0.11671359 | L19: -0.036788892 | M19: 0.97082763 | N19: -0.23983133 | O19: 0.2312438 | P19: -0.23983133 | Q19: 0.2312438
A20: ='ALL VARS'!A20 -> 43955 | B20: ='ALL VARS'!F20 -> 0.0045167588 | C20: ='ALL VARS'!G20 -> 0.0085292502 | D20: ='ALL VARS'!H20 -> -0.010852016 | E20: ='ALL VARS'!T20 -> 0.0036088495 | F20: ='ALL VARS'!V20 -> -0.026772281 | G20: ='ALL VARS'!J20 -> 37.796 | I20: Daily Return-Adj_t_minus_1 | J20: -0.083383264 | K20: 0.11824339 | L20: -0.70518332 | M20: 0.48458889 | N20: -0.32200808 | O20: 0.15524155 | P20: -0.32200808 | Q20: 0.15524155
A21: ='ALL VARS'!A21 -> 43952 | B21: ='ALL VARS'!F21 -> 0.0085292502 | C21: ='ALL VARS'!G21 -> -0.010852016 | D21: ='ALL VARS'!H21 -> -0.029379859 | E21: ='ALL VARS'!T21 -> -0.0034534088 | F21: ='ALL VARS'!V21 -> 0.025287614 | G21: ='ALL VARS'!J21 -> 37.892001 | I21: Sent_t_+_1_k, k=0 | J21: 0.37749811 | K21: 0.26677242 | L21: 1.4150567 | M21: 0.16442393 | N21: -0.16087044 | O21: 0.91586666 | P21: -0.16087044 | Q21: 0.91586666
A22: ='ALL VARS'!A22 -> 43951 | B22: ='ALL VARS'!F22 -> -0.010852016 | C22: ='ALL VARS'!G22 -> -0.029379859 | D22: ='ALL VARS'!H22 -> 0.029043864 | E22: ='ALL VARS'!T22 -> -0.0024350382 | F22: ='ALL VARS'!V22 -> 0.016379305 | G22: ='ALL VARS'!J22 -> 38.488001 | I22: Sent_t_+_1_k, k=0 * (VIX_10_t minus VIX_bar_10) | J22: 0.029867522 | K22: 0.024474015 | L22: 1.2203768 | M22: 0.22912987 | N22: -0.019523041 | O22: 0.079258084 | P22: -0.019523041 | Q22: 0.079258084
A23: ='ALL VARS'!A23 -> 43950 | B23: ='ALL VARS'!F23 -> -0.029379859 | C23: ='ALL VARS'!G23 -> 0.029043864 | D23: ='ALL VARS'!H23 -> 0.010667882 | E23: ='ALL VARS'!T23 -> -0.0020812126 | F23: ='ALL VARS'!V23 -> 0.011999249 | G23: ='ALL VARS'!J23 -> 39.449001 | I23: VIX_10_t | J23: 0.00015983346 | K23: 7.3087962e-05 | L23: 2.1868644 | M23: 0.034373247 | N23: 1.2335981e-05 | O23: 0.00030733094 | P23: 1.2335981e-05 | Q23: 0.00030733094
A24: ='ALL VARS'!A24 -> 43949 | B24: ='ALL VARS'!F24 -> 0.029043864 | C24: ='ALL VARS'!G24 -> 0.010667882 | D24: ='ALL VARS'!H24 -> 0.015373999 | E24: ='ALL VARS'!T24 -> 8.9372304e-05 | F24: ='ALL VARS'!V24 -> -0.00047782978 | G24: ='ALL VARS'!J24 -> 39.868001
A25: ='ALL VARS'!A25 -> 43948 | B25: ='ALL VARS'!F25 -> 0.010667882 | C25: ='ALL VARS'!G25 -> 0.015373999 | D25: ='ALL VARS'!H25 -> 0.01187984 | E25: ='ALL VARS'!T25 -> -0.0023627441 | F25: ='ALL VARS'!V25 -> 0.01077059 | G25: ='ALL VARS'!J25 -> 40.656
A26: ='ALL VARS'!A26 -> 43945 | B26: ='ALL VARS'!F26 -> 0.015373999 | C26: ='ALL VARS'!G26 -> 0.01187984 | D26: ='ALL VARS'!H26 -> -0.0025965892 | E26: ='ALL VARS'!T26 -> -0.0063264485 | F26: ='ALL VARS'!V26 -> 0.025207791 | G26: ='ALL VARS'!J26 -> 41.23
A27: ='ALL VARS'!A27 -> 43944 | B27: ='ALL VARS'!F27 -> 0.01187984 | C27: ='ALL VARS'!G27 -> -0.0025965892 | D27: ='ALL VARS'!H27 -> 0.024971169 | E27: ='ALL VARS'!T27 -> -0.00039553488 | F27: ='ALL VARS'!V27 -> 0.001498092 | G27: ='ALL VARS'!J27 -> 41.427
A28: ='ALL VARS'!A28 -> 43943 | B28: ='ALL VARS'!F28 -> -0.0025965892 | C28: ='ALL VARS'!G28 -> 0.024971169 | D28: ='ALL VARS'!H28 -> -0.031150324 | E28: ='ALL VARS'!T28 -> -0.0081406529 | F28: ='ALL VARS'!V28 -> 0.02699041 | G28: ='ALL VARS'!J28 -> 41.899
A29: ='ALL VARS'!A29 -> 43942 | B29: ='ALL VARS'!F29 -> 0.024971169 | C29: ='ALL VARS'!G29 -> -0.031150324 | D29: ='ALL VARS'!H29 -> 0.0019776888 | E29: ='ALL VARS'!T29 -> 0.00093619015 | F29: ='ALL VARS'!V29 -> -0.0031198621 | G29: ='ALL VARS'!J29 -> 41.882
A30: ='ALL VARS'!A30 -> 43941 | B30: ='ALL VARS'!F30 -> -0.031150324 | C30: ='ALL VARS'!G30 -> 0.0019776888 | D30: ='ALL VARS'!H30 -> 0.033138402 | E30: ='ALL VARS'!T30 -> 0.00093990533 | F30: ='ALL VARS'!V30 -> -0.0028530914 | G30: ='ALL VARS'!J30 -> 42.179
A31: ='ALL VARS'!A31 -> 43938 | B31: ='ALL VARS'!F31 -> 0.0019776888 | C31: ='ALL VARS'!G31 -> 0.033138402 | D31: ='ALL VARS'!H31 -> -0.0042482631 | E31: ='ALL VARS'!T31 -> 0.033249417 | F31: ='ALL VARS'!V31 -> -0.058502666 | G31: ='ALL VARS'!J31 -> 43.454999
A32: ='ALL VARS'!A32 -> 43937 | B32: ='ALL VARS'!F32 -> 0.033138402 | C32: ='ALL VARS'!G32 -> -0.0042482631 | D32: ='ALL VARS'!H32 -> -0.021026256 | E32: ='ALL VARS'!T32 -> -0.00020033672 | F32: ='ALL VARS'!V32 -> 1.2923625e-05 | G32: ='ALL VARS'!J32 -> 45.149999
A33: ='ALL VARS'!A33 -> 43936 | B33: ='ALL VARS'!F33 -> -0.0042482631 | C33: ='ALL VARS'!G33 -> -0.021026256 | D33: ='ALL VARS'!H33 -> 0.012965423 | E33: ='ALL VARS'!T33 -> -0.0017813607 | F33: ='ALL VARS'!V33 -> -0.0021474135 | G33: ='ALL VARS'!J33 -> 46.42
A34: ='ALL VARS'!A34 -> 43935 | B34: ='ALL VARS'!F34 -> -0.021026256 | C34: ='ALL VARS'!G34 -> 0.012965423 | D34: ='ALL VARS'!H34 -> -0.006402328 | E34: ='ALL VARS'!T34 -> -0.0048918311 | F34: ='ALL VARS'!V34 -> -0.015348076 | G34: ='ALL VARS'!J34 -> 48.352
A35: ='ALL VARS'!A35 -> 43934 | B35: ='ALL VARS'!F35 -> 0.012965423 | C35: ='ALL VARS'!G35 -> -0.006402328 | D35: ='ALL VARS'!H35 -> 0.017298909 | E35: ='ALL VARS'!T35 -> 0.0016972292 | F35: ='ALL VARS'!V35 -> 0.0094611892 | G35: ='ALL VARS'!J35 -> 50.789
... A48: ='ALL VARS'!A48 -> 43914 | B48: ='ALL VARS'!F48 -> 0.045191002 | C48: ='ALL VARS'!G48 -> 0.1195707 | D48: ='ALL VARS'!H48 -> -0.052591152 | E48: ='ALL VARS'!T48 -> 0.0012419563 | F48: ='ALL VARS'!V48 -> 0.026954787 | G48: ='ALL VARS'!J48 -> 66.918001

Sheet Eq4 avec Sent__t_+_1_k, k=1
A1: ='ALL VARS'!A1 -> Date | B1: ='ALL VARS'!F1 -> Daily Return-Adj_t_+1 | C1: ='ALL VARS'!G1 -> Daily Return-Adj_t | D1: ='ALL VARS'!H1 -> Daily Return-Adj_t_minus_1 | E1: ='ALL VARS'!X1 -> Sent_t_+_1_k, k=1 | F1: ='ALL VARS'!Z1 -> Sent_t_+_1_k, k=1 * (VIX_10_t minus VIX_bar_10) | G1: ='ALL VARS'!J1 -> VIX_10_t
A2: ='ALL VARS'!A2 -> 43980 | B2: ='ALL VARS'!F2 -> 0.02309392 | C2: ='ALL VARS'!G2 -> -0.0045798181 | D2: ='ALL VARS'!H2 -> -0.0006089448 | E2: ='ALL VARS'!X2 -> -0.00048347977 | F2: ='ALL VARS'!Z2 -> 0.0076348751 | G2: ='ALL VARS'!J2 -> 29.423 | I2: RAPPORT DÉTAILLÉ
A3: ='ALL VARS'!A3 -> 43979 | B3: ='ALL VARS'!F3 -> -0.0045798181 | C3: ='ALL VARS'!G3 -> -0.0006089448 | D3: ='ALL VARS'!H3 -> 0.0081792696 | E3: ='ALL VARS'!X3 -> -0.0039796702 | F3: ='ALL VARS'!Z3 -> 0.060182598 | G3: ='ALL VARS'!J3 -> 30.092
A4: ='ALL VARS'!A4 -> 43978 | B4: ='ALL VARS'!F4 -> -0.0006089448 | C4: ='ALL VARS'!G4 -> 0.0081792696 | D4: ='ALL VARS'!H4 -> 0.0048223739 | E4: ='ALL VARS'!X4 -> 0.0001392067 | F4: ='ALL VARS'!Z4 -> -0.0020297045 | G4: ='ALL VARS'!J4 -> 30.634 | I4: Statistiques de la régression
A5: ='ALL VARS'!A5 -> 43977 | B5: ='ALL VARS'!F5 -> 0.0081792696 | C5: ='ALL VARS'!G5 -> 0.0048223739 | D5: ='ALL VARS'!H5 -> 0.010849211 | E5: ='ALL VARS'!X5 -> -0.003560953 | F5: ='ALL VARS'!Z5 -> 0.052077188 | G5: ='ALL VARS'!J5 -> 30.59 | I5: Coefficient de détermination multiple | J5: 0.35975002
A6: ='ALL VARS'!A6 -> 43976 | B6: ='ALL VARS'!F6 -> 0.0048223739 | C6: ='ALL VARS'!G6 -> 0.010849211 | D6: ='ALL VARS'!H6 -> 0.0019280759 | E6: ='ALL VARS'!X6 -> 0.0022717113 | F6: ='ALL VARS'!Z6 -> -0.033243108 | G6: ='ALL VARS'!J6 -> 30.581 | I6: Coefficient de détermination R^2 | J6: 0.12942008
A7: ='ALL VARS'!A7 -> 43973 | B7: ='ALL VARS'!F7 -> 0.010849211 | C7: ='ALL VARS'!G7 -> 0.0019280759 | D7: ='ALL VARS'!H7 -> -0.0075144837 | E7: ='ALL VARS'!X7 -> -0.011963391 | F7: ='ALL VARS'!Z7 -> 0.17517405 | G7: ='ALL VARS'!J7 -> 30.572 | I7: Coefficient de détermination R^2 | J7: 0.022698182
A8: ='ALL VARS'!A8 -> 43972 | B8: ='ALL VARS'!F8 -> 0.0019280759 | C8: ='ALL VARS'!G8 -> -0.0075144837 | D8: ='ALL VARS'!H8 -> 0.0075307923 | E8: ='ALL VARS'!X8 -> 0.00074224152 | F8: ='ALL VARS'!Z8 -> -0.01072651 | G8: ='ALL VARS'!J8 -> 30.763 | I8: Erreur-type | J8: 0.020207828
A9: ='ALL VARS'!A9 -> 43971 | B9: ='ALL VARS'!F9 -> -0.0075144837 | C9: ='ALL VARS'!G9 -> 0.0075307923 | D9: ='ALL VARS'!H9 -> 0.016845501 | E9: ='ALL VARS'!X9 -> 0.0015145366 | F9: ='ALL VARS'!Z9 -> -0.020958929 | G9: ='ALL VARS'!J9 -> 31.376 | I9: Observations | J9: 47
A10: ='ALL VARS'!A10 -> 43970 | B10: ='ALL VARS'!F10 -> 0.0075307923 | C10: ='ALL VARS'!G10 -> 0.016845501 | D10: ='ALL VARS'!H10 -> 0.0089044015 | E10: ='ALL VARS'!X10 -> 0.0087604672 | F10: ='ALL VARS'!Z10 -> -0.11853358 | G10: ='ALL VARS'!J10 -> 31.684
A11: ='ALL VARS'!A11 -> 43966 | B11: ='ALL VARS'!F11 -> 0.016845501 | C11: ='ALL VARS'!G11 -> 0.0089044015 | D11: ='ALL VARS'!H11 -> 0.00044817695 | E11: ='ALL VARS'!X11 -> 0.0083455874 | F11: ='ALL VARS'!Z11 -> -0.10293038 | G11: ='ALL VARS'!J11 -> 32.881 | I11: ANALYSE DE VARIANCE
A12: ='ALL VARS'!A12 -> 43965 | B12: ='ALL VARS'!F12 -> 0.0089044015 | C12: ='ALL VARS'!G12 -> 0.00044817695 | D12: ='ALL VARS'!H12 -> -0.025401177 | E12: ='ALL VARS'!X12 -> -0.0074675971 | F12: ='ALL VARS'!Z12 -> 0.090951664 | G12: ='ALL VARS'!J12 -> 33.035 | J12: Degré de liberté | K12: Somme des carrés | L12: Moyenne des carrés | M12: F | N12: Valeur critique de F
A13: ='ALL VARS'!A13 -> 43964 | B13: ='ALL VARS'!F13 -> 0.00044817695 | C13: ='ALL VARS'!G13 -> -0.025401177 | D13: ='ALL VARS'!H13 -> -0.014698872 | E13: ='ALL VARS'!X13 -> 0.0052177766 | F13: ='ALL VARS'!Z13 -> -0.065663155 | G13: ='ALL VARS'!J13 -> 32.63 | I13: Régression | J13: 5 | K13: 0.002549656 | L13: 0.0005099312 | M13: 1.2487408 | N13: 0.30439081
A14: ='ALL VARS'!A14 -> 43963 | B14: ='ALL VARS'!F14 -> -0.025401177 | C14: ='ALL VARS'!G14 -> -0.014698872 | D14: ='ALL VARS'!H14 -> 0.0091270288 | E14: ='ALL VARS'!X14 -> 0.0021353922 | F14: ='ALL VARS'!Z14 -> -0.026759686 | G14: ='ALL VARS'!J14 -> 32.683 | I14: Résidus | J14: 42 | K14: 0.017150965 | L14: 0.00040835632
A15: ='ALL VARS'!A15 -> 43962 | B15: ='ALL VARS'!F15 -> -0.014698872 | C15: ='ALL VARS'!G15 -> 0.0091270288 | D15: ='ALL VARS'!H15 -> 0.0089592895 | E15: ='ALL VARS'!X15 -> -0.011690442 | F15: ='ALL VARS'!Z15 -> 0.13981195 | G15: ='ALL VARS'!J15 -> 33.255 | I15: Total | J15: 47 | K15: 0.019700621
A16: ='ALL VARS'!A16 -> 43959 | B16: ='ALL VARS'!F16 -> 0.0091270288 | C16: ='ALL VARS'!G16 -> 0.0089592895 | D16: ='ALL VARS'!H16 -> 0.0002022831 | E16: ='ALL VARS'!X16 -> 0.0015915757 | F16: ='ALL VARS'!Z16 -> -0.01776916 | G16: ='ALL VARS'!J16 -> 34.05
A17: ='ALL VARS'!A17 -> 43958 | B17: ='ALL VARS'!F17 -> 0.0089592895 | C17: ='ALL VARS'!G17 -> 0.0002022831 | D17: ='ALL VARS'!H17 -> 0.0012895694 | E17: ='ALL VARS'!X17 -> 0.0042867612 | F17: ='ALL VARS'!Z17 -> -0.043598541 | G17: ='ALL VARS'!J17 -> 35.044 | J17: Coefficients | K17: Erreur-type | L17: Statistique t | M17: Probabilité | N17: Limite inférieure pour seuil de confiance = 95% | O17: Limite supérieure pour seuil de confiance = 95% | P17: Limite inférieure pour seuil de confiance = 95,0% | Q17: Limite supérieure pour seuil de confiance = 95,0%
A18: ='ALL VARS'!A18 -> 43957 | B18: ='ALL VARS'!F18 -> 0.0002022831 | C18: ='ALL VARS'!G18 -> 0.0012895694 | D18: ='ALL VARS'!H18 -> 0.0045167588 | E18: ='ALL VARS'!X18 -> -0.0035819131 | F18: ='ALL VARS'!Z18 -> 0.033614494 | G18: ='ALL VARS'!J18 -> 35.83 | I18: Constante | J18: 0 | K18: #N/A | L18: #N/A | M18: #N/A | N18: #N/A | O18: #N/A | P18: #N/A | Q18: #N/A
A19: ='ALL VARS'!A19 -> 43956 | B19: ='ALL VARS'!F19 -> 0.0012895694 | C19: ='ALL VARS'!G19 -> 0.0045167588 | D19: ='ALL VARS'!H19 -> 0.0085292502 | E19: ='ALL VARS'!X19 -> -0.00038911297 | F19: ='ALL VARS'!Z19 -> 0.0031924807 | G19: ='ALL VARS'!J19 -> 37.01 | I19: Daily Return-Adj_t | J19: 0.023691013 | K19: 0.12010718 | L19: 0.19724892 | M19: 0.84458424 | N19: -0.2186951 | O19: 0.26607712 | P19: -0.2186951 | Q19: 0.26607712
A20: ='ALL VARS'!A20 -> 43955 | B20: ='ALL VARS'!F20 -> 0.0045167588 | C20: ='ALL VARS'!G20 -> 0.0085292502 | D20: ='ALL VARS'!H20 -> -0.010852016 | E20: ='ALL VARS'!X20 -> 0.0036088051 | F20: ='ALL VARS'!Z20 -> -0.026771951 | G20: ='ALL VARS'!J20 -> 37.796 | I20: Daily Return-Adj_t_minus_1 | J20: -0.11099172 | K20: 0.11737104 | L20: -0.94564823 | M20: 0.34973694 | N20: -0.34785607 | O20: 0.12587263 | P20: -0.34785607 | Q20: 0.12587263
A21: ='ALL VARS'!A21 -> 43952 | B21: ='ALL VARS'!F21 -> 0.0085292502 | C21: ='ALL VARS'!G21 -> -0.010852016 | D21: ='ALL VARS'!H21 -> -0.029379859 | E21: ='ALL VARS'!X21 -> -0.0034532711 | F21: ='ALL VARS'!Z21 -> 0.025286606 | G21: ='ALL VARS'!J21 -> 37.892001 | I21: Sent_t_+_1_k, k=1 | J21: 0.68568449 | K21: 0.49589816 | L21: 1.3827123 | M21: 0.17406124 | N21: -0.31507852 | O21: 1.6864475 | P21: -0.31507852 | Q21: 1.6864475
A22: ='ALL VARS'!A22 -> 43951 | B22: ='ALL VARS'!F22 -> -0.010852016 | C22: ='ALL VARS'!G22 -> -0.029379859 | D22: ='ALL VARS'!H22 -> 0.029043864 | E22: ='ALL VARS'!X22 -> -0.0024349164 | F22: ='ALL VARS'!Z22 -> 0.016378485 | G22: ='ALL VARS'!J22 -> 38.488001 | I22: Sent_t_+_1_k, k=1 * (VIX_10_t minus VIX_bar_10) | J22: 0.016615185 | K22: 0.035631895 | L22: 0.4663009 | M22: 0.64340971 | N22: -0.055292891 | O22: 0.08852326 | P22: -0.055292891 | Q22: 0.08852326
A23: ='ALL VARS'!A23 -> 43950 | B23: ='ALL VARS'!F23 -> -0.029379859 | C23: ='ALL VARS'!G23 -> 0.029043864 | D23: ='ALL VARS'!H23 -> 0.010667882 | E23: ='ALL VARS'!X23 -> -0.0062578891 | F23: ='ALL VARS'!Z23 -> 0.036079911 | G23: ='ALL VARS'!J23 -> 39.449001 | I23: VIX_10_t | J23: 0.00013295148 | K23: 7.1867748e-05 | L23: 1.8499463 | M23: 0.0713653 | N23: -1.2083512e-05 | O23: 0.00027798646 | P23: -1.2083512e-05 | Q23: 0.00027798646
A24: ='ALL VARS'!A24 -> 43949 | B24: ='ALL VARS'!F24 -> 0.029043864 | C24: ='ALL VARS'!G24 -> 0.010667882 | D24: ='ALL VARS'!H24 -> 0.015373999 | E24: ='ALL VARS'!X24 -> 8.9372642e-05 | F24: ='ALL VARS'!Z24 -> -0.00047783159 | G24: ='ALL VARS'!J24 -> 39.868001
A25: ='ALL VARS'!A25 -> 43948 | B25: ='ALL VARS'!F25 -> 0.010667882 | C25: ='ALL VARS'!G25 -> 0.015373999 | D25: ='ALL VARS'!H25 -> 0.01187984 | E25: ='ALL VARS'!X25 -> -0.0023627545 | F25: ='ALL VARS'!Z25 -> 0.010770637 | G25: ='ALL VARS'!J25 -> 40.656
A26: ='ALL VARS'!A26 -> 43945 | B26: ='ALL VARS'!F26 -> 0.015373999 | C26: ='ALL VARS'!G26 -> 0.01187984 | D26: ='ALL VARS'!H26 -> -0.0025965892 | E26: ='ALL VARS'!X26 -> -0.0063268426 | F26: ='ALL VARS'!Z26 -> 0.025209361 | G26: ='ALL VARS'!J26 -> 41.23
A27: ='ALL VARS'!A27 -> 43944 | B27: ='ALL VARS'!F27 -> 0.01187984 | C27: ='ALL VARS'!G27 -> -0.0025965892 | D27: ='ALL VARS'!H27 -> 0.024971169 | E27: ='ALL VARS'!X27 -> -0.0014570748 | F27: ='ALL VARS'!Z27 -> 0.0055186843 | G27: ='ALL VARS'!J27 -> 41.427
A28: ='ALL VARS'!A28 -> 43943 | B28: ='ALL VARS'!F28 -> -0.0025965892 | C28: ='ALL VARS'!G28 -> 0.024971169 | D28: ='ALL VARS'!H28 -> -0.031150324 | E28: ='ALL VARS'!X28 -> -0.0081397417 | F28: ='ALL VARS'!Z28 -> 0.026987389 | G28: ='ALL VARS'!J28 -> 41.899
A29: ='ALL VARS'!A29 -> 43942 | B29: ='ALL VARS'!F29 -> 0.024971169 | C29: ='ALL VARS'!G29 -> -0.031150324 | D29: ='ALL VARS'!H29 -> 0.0019776888 | E29: ='ALL VARS'!X29 -> 0.0062544683 | F29: ='ALL VARS'!Z29 -> -0.020843072 | G29: ='ALL VARS'!J29 -> 41.882
A30: ='ALL VARS'!A30 -> 43941 | B30: ='ALL VARS'!F30 -> -0.031150324 | C30: ='ALL VARS'!G30 -> 0.0019776888 | D30: ='ALL VARS'!H30 -> 0.033138402 | E30: ='ALL VARS'!X30 -> 0.00093990221 | F30: ='ALL VARS'!Z30 -> -0.0028530819 | G30: ='ALL VARS'!J30 -> 42.179
A31: ='ALL VARS'!A31 -> 43938 | B31: ='ALL VARS'!F31 -> 0.0019776888 | C31: ='ALL VARS'!G31 -> 0.033138402 | D31: ='ALL VARS'!H31 -> -0.0042482631 | E31: ='ALL VARS'!X31 -> 0.015092007 | F31: ='ALL VARS'!Z31 -> -0.02655453 | G31: ='ALL VARS'!J31 -> 43.454999
A32: ='ALL VARS'!A32 -> 43937 | B32: ='ALL VARS'!F32 -> 0.033138402 | C32: ='ALL VARS'!G32 -> -0.0042482631 | D32: ='ALL VARS'!H32 -> -0.021026256 | E32: ='ALL VARS'!X32 -> -0.00020035314 | F32: ='ALL VARS'!Z32 -> 1.2924684e-05 | G32: ='ALL VARS'!J32 -> 45.149999
A33: ='ALL VARS'!A33 -> 43936 | B33: ='ALL VARS'!F33 -> -0.0042482631 | C33: ='ALL VARS'!G33 -> -0.021026256 | D33: ='ALL VARS'!H33 -> 0.012965423 | E33: ='ALL VARS'!X33 -> -0.00025983841 | F33: ='ALL VARS'!Z33 -> -0.00031323276 | G33: ='ALL VARS'!J33 -> 46.42
A34: ='ALL VARS'!A34 -> 43935 | B34: ='ALL VARS'!F34 -> -0.021026256 | C34: ='ALL VARS'!G34 -> 0.012965423 | D34: ='ALL VARS'!H34 -> -0.006402328 | E34: ='ALL VARS'!X34 -> -0.0048918098 | F34: ='ALL VARS'!Z34 -> -0.015348009 | G34: ='ALL VARS'!J34 -> 48.352
A35: ='ALL VARS'!A35 -> 43934 | B35: ='ALL VARS'!F35 -> 0.012965423 | C35: ='ALL VARS'!G35 -> -0.006402328 | D35: ='ALL VARS'!H35 -> 0.017298909 | E35: ='ALL VARS'!X35 -> 0.0016972061 | F35: ='ALL VARS'!Z35 -> 0.0094610608 | G35: ='ALL VARS'!J35 -> 50.789
... A48: ='ALL VARS'!A48 -> 43914 | B48: ='ALL VARS'!F48 -> 0.045191002 | C48: ='ALL VARS'!G48 -> 0.1195707 | D48: ='ALL VARS'!H48 -> -0.052591152 | E48: ='ALL VARS'!X48 -> 0.0012419151 | F48: ='ALL VARS'!Z48 -> 0.026953894 | G48: ='ALL VARS'!J48 -> 66.918001

Sheet Eq4 avec Sent__t_+_1_k, k=2
A1: ='ALL VARS'!A1 -> Date | B1: ='ALL VARS'!F1 -> Daily Return-Adj_t_+1 | C1: ='ALL VARS'!G1 -> Daily Return-Adj_t | D1: ='ALL VARS'!H1 -> Daily Return-Adj_t_minus_1 | E1: ='ALL VARS'!AB1 -> Sent_t_+_1_k, k=2 | F1: ='ALL VARS'!AD1 -> Sent_t_+_1_k, k=2 * (VIX_10_t minus VIX_bar_10) | G1: ='ALL VARS'!J1 -> VIX_10_t
A2: ='ALL VARS'!A2 -> 43980 | B2: ='ALL VARS'!F2 -> 0.02309392 | C2: ='ALL VARS'!G2 -> -0.0045798181 | D2: ='ALL VARS'!H2 -> -0.0006089448 | E2: ='ALL VARS'!AB2 -> -0.002675892 | F2: ='ALL VARS'!AD2 -> 0.042256372 | G2: ='ALL VARS'!J2 -> 29.423 | I2: RAPPORT DÉTAILLÉ
A3: ='ALL VARS'!A3 -> 43979 | B3: ='ALL VARS'!F3 -> -0.0045798181 | C3: ='ALL VARS'!G3 -> -0.0006089448 | D3: ='ALL VARS'!H3 -> 0.0081792696 | E3: ='ALL VARS'!AB3 -> -0.0039797237 | F3: ='ALL VARS'!AD3 -> 0.060183407 | G3: ='ALL VARS'!J3 -> 30.092
A4: ='ALL VARS'!A4 -> 43978 | B4: ='ALL VARS'!F4 -> -0.0006089448 | C4: ='ALL VARS'!G4 -> 0.0081792696 | D4: ='ALL VARS'!H4 -> 0.0048223739 | E4: ='ALL VARS'!AB4 -> 0.0001392248 | F4: ='ALL VARS'!AD4 -> -0.0020299684 | G4: ='ALL VARS'!J4 -> 30.634 | I4: Statistiques de la régression
